Workbook

Sheet Daily Retun & Risk
A1: Date | B1: M&M Stock Price (Daily) | C1: Simple Return (Ri) =[ Pt-P(t-1)/P(t-1)] | D1: Ri=Lognormal formula: LN(Pt/P(t-1) | E1: Add 1 | F1: Probability (Pi) | G1: Er = Sum of ( Ri*Pi) | H1: Variance= (Ri-Er)^2)*Pi | J1: Wipro | K1: Ri | L1: Er = Sum of ( Ri*Pi) | M1: Variance= (Ri-Er)^2)*Pi | O1: Torrent Power | P1: Ri | Q1: Er = Sum of ( Ri*Pi) | R1: Variance= (Ri-Er)^2)*Pi
A2: 45982 | B2: 3749.6 | C2: =(B2-B3)/B3 -> 0.0088519385 | D2: =LN(B2/B3) -> 0.0088129898 | E2: =D2+1 -> 1.008813 | F2: =1/247 -> 0.004048583 | G2: =D2*F2 -> 3.5680121e-05 | H2: =(D2-$G$254)^2*F2 -> 2.5723946e-07 | J2: 244.49 | K2: =LN(J2/J3) -> -0.0072134801 | L2: =K2*F2 -> -2.9204373e-05 | M2: =(K2-$L$254)^2*F2 -> 1.7132776e-07 | O2: 1291.4 | P2: =LN(O2/O3) -> -0.017272912 | Q2: =P2*F2 -> -6.993082e-05 | R2: =(P2-$Q$254)^2*F2 -> 1.0848102e-06
A3: 45981 | B3: 3716.7 | C3: =(B3-B4)/B4 -> -0.0015580927 | D3: =LN(B3/B4) -> -0.0015593078 | E3: =D3+1 -> 0.99844069 | F3: =1/247 -> 0.004048583 | G3: =D3*F3 -> -6.3129869e-06 | H3: =(D3-$G$254)^2*F3 -> 2.3343468e-08 | J3: 246.26 | K3: =LN(J3/J4) -> 0.00077184006 | L3: =K3*F3 -> 3.1248586e-06 | M3: =(K3-$L$254)^2*F3 -> 8.8691525e-09 | O3: 1313.9 | P3: =LN(O3/O4) -> 0.010020354 | Q3: =P3*F3 -> 4.0568234e-05 | R3: =(P3-$Q$254)^2*F3 -> 4.8314554e-07
A4: 45980 | B4: 3722.5 | C4: =(B4-B5)/B5 -> 0.0074970228 | D4: =LN(B4/B5) -> 0.0074690598 | E4: =D4+1 -> 1.0074691 | F4: =1/247 -> 0.004048583 | G4: =D4*F4 -> 3.0239109e-05 | H4: =(D4-$G$254)^2*F4 -> 1.778103e-07 | J4: 246.07 | K4: =LN(J4/J5) -> 0.021234139 | L4: =K4*F4 -> 8.5968173e-05 | M4: =(K4-$L$254)^2*F4 -> 1.9492657e-06 | O4: 1300.8 | P4: =LN(O4/O5) -> -0.0094112941 | Q4: =P4*F4 -> -3.8102405e-05 | R4: =(P4-$Q$254)^2*F4 -> 2.9302673e-07
A5: 45979 | B5: 3694.8 | C5: =(B5-B6)/B6 -> -0.010736566 | D5: =LN(B5/B6) -> -0.010794619 | E5: =D5+1 -> 0.98920538 | F5: =1/247 -> 0.004048583 | G5: =D5*F5 -> -4.370291e-05 | H5: =(D5-$G$254)^2*F5 -> 5.4821357e-07 | J5: 240.9 | K5: =LN(J5/J6) -> -0.012991213 | L5: =K5*F5 -> -5.2596003e-05 | M5: =(K5-$L$254)^2*F5 -> 6.1081399e-07 | O5: 1313.1 | P5: =LN(O5/O6) -> 0.0023636167 | Q5: =P5*F5 -> 9.5692983e-06 | R5: =(P5-$Q$254)^2*F5 -> 4.3222491e-08
A6: 45978 | B6: 3734.9 | C6: =(B6-B7)/B7 -> 0.0098145244 | D6: =LN(B6/B7) -> 0.0097666748 | E6: =D6+1 -> 1.0097667 | F6: =1/247 -> 0.004048583 | G6: =D6*F6 -> 3.9541194e-05 | H6: =(D6-$G$254)^2*F6 -> 3.2247557e-07 | J6: 244.05 | K6: =LN(J6/J7) -> -0.0013103478 | L6: =K6*F6 -> -5.305052e-06 | M6: =(K6-$L$254)^2*F6 -> 1.4676764e-09 | O6: 1310 | P6: =LN(O6/O7) -> 0.0068939377 | Q6: =P6*F6 -> 2.7910679e-05 | R6: =(P6-$Q$254)^2*F6 -> 2.4617238e-07
A7: 45975 | B7: 3698.6 | C7: =(B7-B8)/B8 -> -0.00024327612 | D7: =LN(B7/B8) -> -0.00024330571 | E7: =D7+1 -> 0.99975669 | F7: =1/247 -> 0.004048583 | G7: =D7*F7 -> -9.8504338e-07 | H7: =(D7-$G$254)^2*F7 -> 4.7679697e-09 | J7: 244.37 | K7: =LN(J7/J8) -> -0.0039207728 | L7: =K7*F7 -> -1.5873574e-05 | M7: =(K7-$L$254)^2*F7 -> 4.178248e-08 | O7: 1301 | P7: =LN(O7/O8) -> 0.0057041702 | Q7: =P7*F7 -> 2.3093807e-05 | R7: =(P7-$Q$254)^2*F7 -> 1.7678201e-07
A8: 45974 | B8: 3699.5 | C8: =(B8-B9)/B9 -> -0.014596596 | D8: =LN(B8/B9) -> -0.014704174 | E8: =D8+1 -> 0.98529583 | F8: =1/247 -> 0.004048583 | G8: =D8*F8 -> -5.953107e-05 | H8: =(D8-$G$254)^2*F8 -> 9.7846426e-07 | J8: 245.33 | K8: =LN(J8/J9) -> 0.00044847621 | L8: =K8*F8 -> 1.8156931e-06 | M8: =(K8-$L$254)^2*F8 -> 5.4171114e-09 | O8: 1293.6 | P8: =LN(O8/O9) -> 0.0006186205 | Q8: =P8*F8 -> 2.5045364e-06 | R8: =(P8-$Q$254)^2*F8 -> 9.3835543e-09
A9: 45973 | B9: 3754.3 | C9: =(B9-B10)/B10 -> 0.0013869995 | D9: =LN(B9/B10) -> 0.0013860386 | E9: =D9+1 -> 1.001386 | F9: =1/247 -> 0.004048583 | G9: =D9*F9 -> 5.6114921e-06 | H9: =(D9-$G$254)^2*F9 -> 1.1986972e-09 | J9: 245.22 | K9: =LN(J9/J10) -> 0.014499854 | L9: =K9*F9 -> 5.8703861e-05 | M9: =(K9-$L$254)^2*F9 -> 9.3638283e-07 | O9: 1292.8 | P9: =LN(O9/O10) -> -0.03346829 | Q9: =P9*F9 -> -0.00013549915 | R9: =(P9-$Q$254)^2*F9 -> 4.2933058e-06
A10: 45972 | B10: 3749.1 | C10: =(B10-B11)/B11 -> 0.02325391 | D10: =LN(B10/B11) -> 0.022987657 | E10: =D10+1 -> 1.0229877 | F10: =1/247 -> 0.004048583 | G10: =D10*F10 -> 9.3067439e-05 | H10: =(D10-$G$254)^2*F10 -> 1.9855636e-06 | J10: 241.69 | K10: =LN(J10/J11) -> 0.0076838789 | L10: =K10*F10 -> 3.1108821e-05 | M10: =(K10-$L$254)^2*F10 -> 2.8513323e-07 | O10: 1336.8 | P10: =LN(O10/O11) -> 0.01857358 | Q10: =P10*F10 -> 7.5196682e-05 | R10: =(P10-$Q$254)^2*F10 -> 1.5359029e-06
A11: 45971 | B11: 3663.9 | C11: =(B11-B12)/B12 -> -0.007126985 | D11: =LN(B11/B12) -> -0.0071525033 | E11: =D11+1 -> 0.9928475 | F11: =1/247 -> 0.004048583 | G11: =D11*F11 -> -2.8957503e-05 | H11: =(D11-$G$254)^2*F11 -> 2.5874741e-07 | J11: 239.84 | K11: =LN(J11/J12) -> 0.014066111 | L11: =K11*F11 -> 5.6947816e-05 | M11: =(K11-$L$254)^2*F11 -> 8.8373228e-07 | O11: 1312.2 | P11: =LN(O11/O12) -> 0.023907979 | Q11: =P11*F11 -> 9.6793438e-05 | R11: =(P11-$Q$254)^2*F11 -> 2.4924047e-06
A12: 45968 | B12: 3690.2 | C12: =(B12-B13)/B13 -> 0.01981484 | D12: =LN(B12/B13) -> 0.019621082 | E12: =D12+1 -> 1.0196211 | F12: =1/247 -> 0.004048583 | G12: =D12*F12 -> 7.9437578e-05 | H12: =(D12-$G$254)^2*F12 -> 1.4277626e-06 | J12: 236.49 | K12: =LN(J12/J13) -> -0.014941311 | L12: =K12*F12 -> -6.0491139e-05 | M12: =(K12-$L$254)^2*F12 -> 8.2016153e-07 | O12: 1281.2 | P12: =LN(O12/O13) -> 0.0062637223 | Q12: =P12*F12 -> 2.53592e-05 | R12: =(P12-$Q$254)^2*F12 -> 2.0798888e-07
A13: 45967 | B13: 3618.5 | C13: =(B13-B14)/B14 -> 0.010415503 | D13: =LN(B13/B14) -> 0.010361636 | E13: =D13+1 -> 1.0103616 | F13: =1/247 -> 0.004048583 | G13: =D13*F13 -> 4.1949941e-05 | H13: =(D13-$G$254)^2*F13 -> 3.6690371e-07 | J13: 240.05 | K13: =LN(J13/J14) -> 0.0089127523 | L13: =K13*F13 -> 3.6084017e-05 | M13: =(K13-$L$254)^2*F13 -> 3.7475213e-07 | O13: 1273.2 | P13: =LN(O13/O14) -> -0.024133082 | Q13: =P13*F13 -> -9.7704785e-05 | R13: =(P13-$Q$254)^2*F13 -> 2.1846151e-06
... A248: 45622 | B248: 2985.2 | C248: =(B248-B249)/B249 -> -0.019831889 | D248: =LN(B248/B249) -> -0.02003118 | E248: =D248+1 -> 0.97996882 | F248: =1/247 -> 0.004048583 | G248: =D248*F248 -> -8.1097894e-05 | H248: =(D248-$G$254)^2*F248 -> 1.7639101e-06 | J248: 294.5 | K248: =LN(J248/J249) -> 0.01116567 | L248: =K248*F248 -> 4.5205142e-05 | M248: =(K248-$L$254)^2*F248 -> 5.7081009e-07 | O248: 1555.2 | P248: =LN(O248/O249) -> -0.037359216 | Q248: =P248*F248 -> -0.00015125189 | R248: =(P248-$Q$254)^2*F248 -> 5.3805586e-06
A249: 45621 | B249: 3045.6 | J249: 291.23 | O249: 1614.4
A250: =COUNT(B2:B249) -> 248
A252: 1 | B252: AM (Daily) | C252: =AVERAGE(C2:C248) -> 0.00099126535 | D252: =AVERAGE(D2:D248) -> 0.00084190786
A253: 2 | B253: GM (Daily growth rate) | C253: =GEOMEAN(E2:E248) -> 1.0006927 | D253: =C253-1 -> 0.00069274373
A254: 3 | B254: Expected Return | C254: sum of (Ri*Pi) | G254: =SUM(G2:G248) -> 0.00084190786 | L254: =SUM(L2:L249) -> -0.00070825476 | Q254: =SUM(Q2:Q249) -> -0.00090379137
A255: 4 | B255: Variance = sum of[(Ri-ER)^2*Pi] | H255: =SUM(H2:H248) -> 0.00029796126 | M255: =SUM(M2:M248) -> 0.00026209884 | R255: =SUM(R2:R248) -> 0.00044488606
A256: 5 | B256: Risk (volatility of not achieving expected return) | C256: sqtr of Variance | H256: =SQRT(H255) -> 0.017261554 | M256: =SQRT(M255) -> 0.016189467 | R256: =SQRT(R255) -> 0.021092322
A257: 6 | B257: Coefficient of Cor | C257: =_xlfn.COVARIANCE.S(D2:D248,K2:K248) -> 7.6285058e-05 | R257: =_xlfn.COVARIANCE.S(D2:D248,P2:P248) -> 0.00010922045
A260: Stock Price Prediction based on return
A261: 24/11/2025 | B261: =B2*(1+D253) -> 3752.1975 | C261: =B2*(1+D252) -> 3752.7568
A263: Stock price prediction based on risk and return
A264: 24/11/2025 | B264: =(B2*(1+G254)) -> 3752.7568
B265: =B264*(1.7262%) -> 64.780088 | C265: Fluctuation
B266: =B264-B265 -> 3687.9767
A267: Price Rang | B267: between 3687.98 to 3752.77
B270: AM (Monthly) | C270: =D252*30 -> 0.025257236
B271: GM (Monthly growth rate) | C271: =D253*30 -> 0.020782312
B272: Expected Return | C272: =G254*30 -> 0.025257236
B273: Variance = sum of[(Ri-ER)^2*Pi] | C273: =H255*30 -> 0.0089388377
B274: Risk (volatility of not achieving expected return) | C274: =H256*30 -> 0.51784663

Sheet Monthly Return Vs. Risk
A1: Date | B1: M&M Stock Price (Daily)
A2: 45962 | B2: 3749.6
A3: 45931 | B3: 3487.2
A4: 45901 | B4: 3427
A5: 45870 | B5: 3199.5
A6: 45839 | B6: 3203.1
A7: 45809 | B7: 3183.2
A8: 45778 | B8: 2976.8
A9: 45748 | B9: 2928.8
A10: 45717 | B10: 2665.8
A11: 45689 | B11: 2585.1
A12: 45658 | B12: 2989.85
A13: 45627 | B13: 3007.1
... A61: 44166 | B61: 720.6

Sheet CAPM
A1: Date | B1: Nifty 50 | C1: Rm = Ln return | D1: M&M (Ri) | E1: Rf =10yrs govt bond = 6.53% pa | F1: Er = Rf+(Rm-Rf)*Beta | N1: CAPM = Er=Rf+(Rm-Rf)Beta
A2: 45982 | B2: 26068.15 | C2: =LN(B2/B3) -> -0.0047454849 | D2: ='Daily Retun & Risk'!D2 -> 0.0088129898 | E2: =6.53%/365 -> 0.00017890411 | F2: =E2+((C2-E2)*$O$27) -> -0.0064272502 | N2: Er | O2: Expected return
A3: 45981 | B3: 26192.15 | C3: =LN(B3/B4) -> 0.0053402571 | D3: ='Daily Retun & Risk'!D3 -> -0.0015593078 | E3: =6.53%/365 -> 0.00017890411 | F3: =E3+((C3-E3)*$O$27) -> 0.0071029497 | N3: Rf | O3: Risk free rate of return | R3: 10 years govt. bonds rate
A4: 45980 | B4: 26052.65 | C4: =LN(B4/B5) -> 0.0054885661 | D4: ='Daily Retun & Risk'!D4 -> 0.0074690598 | E4: =6.53%/365 -> 0.00017890411 | F4: =E4+((C4-E4)*$O$27) -> 0.0073019089 | N4: Rm | O4: Market return (index rate of return)
A5: 45979 | B5: 25910.05 | C5: =LN(B5/B6) -> -0.0039827876 | D5: ='Daily Retun & Risk'!D5 -> -0.010794619 | E5: =6.53%/365 -> 0.00017890411 | F5: =E5+((C5-E5)*$O$27) -> -0.0054040784 | N5: Rm-Rf | O5: Risk premium
A6: 45978 | B6: 26013.45 | C6: =LN(B6/B7) -> 0.0039827876 | D6: ='Daily Retun & Risk'!D6 -> 0.0097666748 | E6: =6.53%/365 -> 0.00017890411 | F6: =E6+((C6-E6)*$O$27) -> 0.0052818806 | N6: Beta | O6: Equity coefficient
A7: 45975 | B7: 25910.05 | C7: =LN(B7/B8) -> 0.0011932991 | D7: ='Daily Retun & Risk'!D7 -> -0.00024330571 | E7: =6.53%/365 -> 0.00017890411 | F7: =E7+((C7-E7)*$O$27) -> 0.0015397328 | N7: Linear Reggression = Y = a+bx
A8: 45974 | B8: 25879.15 | C8: =LN(B8/B9) -> 0.00012945622 | D8: ='Daily Retun & Risk'!D8 -> -0.014704174 | E8: =6.53%/365 -> 0.00017890411 | F8: =E8+((C8-E8)*$O$27) -> 0.00011256889
A9: 45973 | B9: 25875.8 | C9: =LN(B9/B10) -> 0.0070136944 | D9: ='Daily Retun & Risk'!D9 -> 0.0013860386 | E9: =6.53%/365 -> 0.00017890411 | F9: =E9+((C9-E9)*$O$27) -> 0.0093478953
A10: 45972 | B10: 25694.95 | C10: =LN(B10/B11) -> 0.0047045785 | D10: ='Daily Retun & Risk'!D10 -> 0.022987657 | E10: =6.53%/365 -> 0.00017890411 | F10: =E10+((C10-E10)*$O$27) -> 0.0062501757 | N10: SUMMARY OUTPUT
A11: 45971 | B11: 25574.35 | C11: =LN(B11/B12) -> 0.0032134503 | D11: ='Daily Retun & Risk'!D11 -> -0.0071525033 | E11: =6.53%/365 -> 0.00017890411 | F11: =E11+((C11-E11)*$O$27) -> 0.0042498011
A12: 45968 | B12: 25492.3 | C12: =LN(B12/B13) -> -0.00068232621 | D12: ='Daily Retun & Risk'!D12 -> 0.019621082 | E12: =6.53%/365 -> 0.00017890411 | F12: =E12+((C12-E12)*$O$27) -> -0.00097645148 | N12: Regression Statistics
A13: 45967 | B13: 25509.7 | C13: =LN(B13/B14) -> -0.0034417784 | D13: ='Daily Retun & Risk'!D13 -> 0.010361636 | E13: =6.53%/365 -> 0.00017890411 | F13: =E13+((C13-E13)*$O$27) -> -0.004678305 | N13: Multiple R | O13: 0.59236625
A14: 45965 | B14: 25597.65 | C14: =LN(B14/B15) -> -0.006452389 | D14: ='Daily Retun & Risk'!D14 -> 0.0090602435 | E14: =6.53%/365 -> 0.00017890411 | F14: =E14+((C14-E14)*$O$27) -> -0.008717092 | N14: R Square | O14: 0.35089778
A15: 45964 | B15: 25763.35 | C15: =LN(B15/B16) -> 0.0016023948 | D15: ='Daily Retun & Risk'!D15 -> 0.017538574 | E15: =6.53%/365 -> 0.00017890411 | F15: =E15+((C15-E15)*$O$27) -> 0.0020885419 | N15: Adjusted R Square | O15: 0.34824838
A16: 45961 | B16: 25722.1 | C16: =LN(B16/B17) -> -0.0060368459 | D16: ='Daily Retun & Risk'!D16 -> -0.0042636666 | E16: =6.53%/365 -> 0.00017890411 | F16: =E16+((C16-E16)*$O$27) -> -0.0081596336 | N16: Standard Error | O16: 0.013963744
A17: 45960 | B17: 25877.85 | C17: =LN(B17/B18) -> -0.0067800786 | D17: ='Daily Retun & Risk'!D17 -> -0.0092656416 | E17: =6.53%/365 -> 0.00017890411 | F17: =E17+((C17-E17)*$O$27) -> -0.0091566934 | N17: Observations | O17: 247
A18: 45959 | B18: 26053.9 | C18: =LN(B18/B19) -> 0.0045277928 | D18: ='Daily Retun & Risk'!D18 -> -0.012482942 | E18: =6.53%/365 -> 0.00017890411 | F18: =E18+((C18-E18)*$O$27) -> 0.0060130147
A19: 45958 | B19: 25936.2 | C19: =LN(B19/B20) -> -0.0011502393 | D19: ='Daily Retun & Risk'!D19 -> -0.0090395153 | E19: =6.53%/365 -> 0.00017890411 | F19: =E19+((C19-E19)*$O$27) -> -0.0016041651 | N19: ANOVA
A20: 45957 | B20: 25966.05 | C20: =LN(B20/B21) -> 0.0066034258 | D20: ='Daily Retun & Risk'!D20 -> -0.0037034009 | E20: =6.53%/365 -> 0.00017890411 | F20: =E20+((C20-E20)*$O$27) -> 0.0087975127 | O20: df | P20: SS | Q20: MS | R20: F | S20: Significance F
A21: 45954 | B21: 25795.15 | C21: =LN(B21/B22) -> -0.0037243775 | D21: ='Daily Retun & Risk'!D21 -> 0.00038628149 | E21: =6.53%/365 -> 0.00017890411 | F21: =E21+((C21-E21)*$O$27) -> -0.0050574166 | N21: Regression | O21: 1 | P21: 0.025824824 | Q21: 0.025824824 | R21: 132.4444 | S21: 8.6992858e-25
A22: 45953 | B22: 25891.4 | C22: =LN(B22/B23) -> 0.00088098924 | D22: ='Daily Retun & Risk'!D22 -> 0.00066254419 | E22: =6.53%/365 -> 0.00017890411 | F22: =E22+((C22-E22)*$O$27) -> 0.0011207636 | N22: Residual | O22: 245 | P22: 0.047771607 | Q22: 0.00019498615
A23: 45951 | B23: 25868.6 | C23: =LN(B23/B24) -> 0.00098430249 | D23: ='Daily Retun & Risk'!D23 -> 0.0061216484 | E23: =6.53%/365 -> 0.00017890411 | F23: =E23+((C23-E23)*$O$27) -> 0.0012593602 | N23: Total | O23: 246 | P23: 0.073596431
A24: 45950 | B24: 25843.15 | C24: =LN(B24/B25) -> 0.0051713886 | D24: ='Daily Retun & Risk'!D24 -> -0.013275936 | E24: =6.53%/365 -> 0.00017890411 | F24: =E24+((C24-E24)*$O$27) -> 0.0068764096
A25: 45947 | B25: 25709.85 | C25: =LN(B25/B26) -> 0.0048562191 | D25: ='Daily Retun & Risk'!D25 -> 0.023974511 | E25: =6.53%/365 -> 0.00017890411 | F25: =E25+((C25-E25)*$O$27) -> 0.0064536043 | O25: Coefficients | P25: Standard Error | Q25: t Stat | R25: P-value | S25: Lower 95% | T25: Upper 95% | U25: Lower 95.0% | V25: Upper 95.0%
A26: 45946 | B26: 25585.3 | C26: =LN(B26/B27) -> 0.010283175 | D26: ='Daily Retun & Risk'!D26 -> 0.01802259 | E26: =6.53%/365 -> 0.00017890411 | F26: =E26+((C26-E26)*$O$27) -> 0.013733961 | N26: Intercept | O26: 0.00044294445 | P26: 0.00088916782 | Q26: 0.49815619 | R26: 0.61882084 | S26: -0.001308444 | T26: 0.0021943329 | U26: -0.001308444 | V26: 0.0021943329
A27: 45945 | B27: 25323.55 | C27: =LN(B27/B28) -> 0.0070558387 | D27: ='Daily Retun & Risk'!D27 -> 0.010751864 | E27: =6.53%/365 -> 0.00017890411 | F27: =E27+((C27-E27)*$O$27) -> 0.0094044326 | N27: Beta | O27: 1.3415176 | P27: 0.11656806 | Q27: 11.508449 | R27: 8.6992858e-25 | S27: 1.1119142 | T27: 1.5711209 | U27: 1.1119142 | V27: 1.5711209
A28: 45944 | B28: 25145.5 | C28: =LN(B28/B29) -> -0.0032497694 | D28: ='Daily Retun & Risk'!D28 -> 2.8903823e-05 | E28: =6.53%/365 -> 0.00017890411 | F28: =E28+((C28-E28)*$O$27) -> -0.0044207215
A29: 45943 | B29: 25227.35 | C29: =LN(B29/B30) -> -0.0022964532 | D29: ='Daily Retun & Risk'!D29 -> 0.0013883669 | E29: =6.53%/365 -> 0.00017890411 | F29: =E29+((C29-E29)*$O$27) -> -0.0031418312
A30: 45940 | B30: 25285.35 | C30: =LN(B30/B31) -> 0.0041036653 | D30: ='Daily Retun & Risk'!D30 -> 0.0034793737 | E30: =6.53%/365 -> 0.00017890411 | F30: =E30+((C30-E30)*$O$27) -> 0.0054440401
A31: 45939 | B31: 25181.8 | C31: =LN(B31/B32) -> 0.0054013883 | D31: ='Daily Retun & Risk'!D31 -> 0.0047748075 | E31: =6.53%/365 -> 0.00017890411 | F31: =E31+((C31-E31)*$O$27) -> 0.0071849583 | N31: RESIDUAL OUTPUT
A32: 45938 | B32: 25046.15 | C32: =LN(B32/B33) -> -0.0024783457 | D32: ='Daily Retun & Risk'!D32 -> -0.019164375 | E32: =6.53%/365 -> 0.00017890411 | F32: =E32+((C32-E32)*$O$27) -> -0.0033858431
A33: 45937 | B33: 25108.3 | C33: =LN(B33/B34) -> 0.0012214576 | D33: ='Daily Retun & Risk'!D33 -> 0.00597291 | E33: =6.53%/365 -> 0.00017890411 | F33: =E33+((C33-E33)*$O$27) -> 0.0015775079 | N33: Observation | O33: Predicted Y | P33: Residuals
A34: 45936 | B34: 25077.65 | C34: =LN(B34/B35) -> 0.0073401581 | D34: ='Daily Retun & Risk'!D34 -> 0.00288434 | E34: =6.53%/365 -> 0.00017890411 | F34: =E34+((C34-E34)*$O$27) -> 0.009785852 | N34: 1 | O34: -0.0059232069 | P34: 0.014736197
A35: 45933 | B35: 24894.25 | C35: =LN(B35/B36) -> 0.0023305604 | D35: ='Daily Retun & Risk'!D35 -> -0.00040430878 | E35: =6.53%/365 -> 0.00017890411 | F35: =E35+((C35-E35)*$O$27) -> 0.0030653888 | N35: 2 | O35: 0.0076069931 | P35: -0.0091663008
A36: 45931 | B36: 24836.3 | C36: =LN(B36/B37) -> 0.009108732 | D36: ='Daily Retun & Risk'!D36 -> 0.010565523 | E36: =6.53%/365 -> 0.00017890411 | F36: =E36+((C36-E36)*$O$27) -> 0.012158425 | N36: 3 | O36: 0.0078059523 | P36: -0.00033689243
A37: 45930 | B37: 24611.1 | C37: =LN(B37/B38) -> -0.00096657604 | D37: ='Daily Retun & Risk'!D37 -> 0.0026004018 | E37: =6.53%/365 -> 0.00017890411 | F37: =E37+((C37-E37)*$O$27) -> -0.0013577776 | N37: 4 | O37: -0.0049000351 | P37: -0.0058945837
A38: 45929 | B38: 24634.9 | C38: =LN(B38/B39) -> -0.00080341496 | D38: ='Daily Retun & Risk'!D38 -> 0.0063393515 | E38: =6.53%/365 -> 0.00017890411 | F38: =E38+((C38-E38)*$O$27) -> -0.0011388942 | N38: 5 | O38: 0.005785924 | P38: 0.0039807508
A39: 45926 | B39: 24654.7 | C39: =LN(B39/B40) -> -0.0095327144 | D39: ='Daily Retun & Risk'!D39 -> -0.038552381 | E39: =6.53%/365 -> 0.00017890411 | F39: =E39+((C39-E39)*$O$27) -> -0.012849403 | N39: 6 | O39: 0.0020437762 | P39: -0.0022870819
A40: 45925 | B40: 24890.85 | C40: =LN(B40/B41) -> -0.0066489726 | D40: ='Daily Retun & Risk'!D40 -> -0.012639333 | E40: =6.53%/365 -> 0.00017890411 | F40: =E40+((C40-E40)*$O$27) -> -0.0089808124 | N40: 7 | O40: 0.00061661224 | P40: -0.015320787
...

Sheet Portfolio Theory
A1: Two asset portfolio
B2: Daily
A3: Security | B3: Er | C3: Variance | D3: SD | E3: Weightage
A4: M&M | B4: ='Daily Retun & Risk'!G254 -> 0.00084190786 | C4: ='Daily Retun & Risk'!H255 -> 0.00029796126 | D4: ='Daily Retun & Risk'!H256 -> 0.017261554 | E4: 0.8
A5: Wipro | B5: ='Daily Retun & Risk'!L254 -> -0.00070825476 | C5: ='Daily Retun & Risk'!M255 -> 0.00026209884 | D5: ='Daily Retun & Risk'!M256 -> 0.016189467 | E5: 0.2
A6: Torrent Power | B6: ='Daily Retun & Risk'!Q254 -> -0.00090379137 | C6: ='Daily Retun & Risk'!R255 -> 0.00044488606 | D6: ='Daily Retun & Risk'!R256 -> 0.021092322
A7: Covariance(M&M & Wipro) | B7: ='Daily Retun & Risk'!C257 -> 7.6285058e-05
A8: Coefficient of corr | B8: =B7/(D4*D5) -> 0.27297761
A9: Covariance (M&M , Torrent) | B9: ='Daily Retun & Risk'!R257 -> 0.00010922045
A10: Coefficient of corr | B10: =B9/(D4*D6) -> 0.29998507
A11: Covariance (Wipro & Torrent) | B11: =_xlfn.COVARIANCE.S('Daily Retun & Risk'!K2:K248,'Daily Retun & Risk'!P2:P248) -> 8.2016871e-05
A12: Coefficient of corr | B12: =B11/(D5*D6) -> 0.2401852
A15: Portfolio Return | B15: =(E4*B4)+(E5*B5) -> 0.00053187534
A16: Portfolio Variance | B16: =(E4)^2*(D4)^2 + (E5)^2*(D5)^2+2*B8*E4*E5*D4*D5 -> 0.00022559038
A17: Portfolio Risk | B17: =SQRT(B16) -> 0.015019666

Sheet Degree of Leverage
A1: Torrent Power | E1: Adani Power
A3: Revenue | B3: 21913 | E3: 12201
A4: VC (75%) | B4: =B3*0.75 -> 16434.75 | D4: VC (34%) | E4: =E3*0.34 -> 4148.34
A5: Contribution | B5: =B3-B4 -> 5478.25 | E5: =E3-E4 -> 8052.66
A7: EBIT | B7: 4368 | E7: 4333
A9: Interest | B9: 874 | E9: 683
A11: EBT | B11: =B7-B9 -> 3494 | E11: =E7-E9 -> 3650
A13: DOL | B13: Contribution/EBIT | C13: =B5/B7 -> 1.2541781 | E13: =E4/E7 -> 0.95738288
A15: DOF | B15: EBIT/EBT | C15: =B7/B11 -> 1.2501431 | E15: =E7/E11 -> 1.1871233
A17: DTL or DCL | B17: Contribution/EBT | C17: =C13*C15 -> 1.5679021 | E17: =E13*E15 -> 1.1365315
