Workbook

Sheet Summary
E2: Interpret the Results
B3: DDM | E3: Current Market Price: 564.15 INR (as of today’s close on 08Jan26). | Q3: Horizon | R3: Beta (β) | S3: R² | T3: Intercept | U3: Observations
B4: =DDM!B14 -> Label | C4: =DDM!C14 -> Value | E4: DDM Valuation: Base case (g = 0%, ke 24.93%) gives 1.00 INR, even optimistic scenarios (g = 4%, ke = 20%) only reach 1.563 INR. | Q4: 3 Years | R4: 2.87 | S4: 0.1471 | T4: −0.07098 | U4: 36
B5: =DDM!B15 -> Latest Dividend (D₀) | C5: =DDM!C15 -> 0.25 | Q5: 5 Years | R5: 2.77 | S5: 0.1707 | T5: −0.01405 | U5: 59
B6: =DDM!B16 -> Growth Rate (g) | C6: =DDM!C16 -> 0 | E6: Observation:
B7: =DDM!B17 -> Next Dividend (D₁) | C7: =DDM!C17 -> 0.25 | E7: DDM valuation is far below the market price because Adani Total Gas pays negligible dividends (0.25 INR annually).
B8: =DDM!B18 -> Required Return (kₑ) | C8: =DDM!C18 -> 0.2493422 | E8: DDM assumes value comes only from dividends, so it undervalues high-growth, low-dividend stocks.
B9: =DDM!B19 -> DDM Valuation: Price (P₀) | C9: =DDM!C19 -> 1.0026381 | E9: Market price reflects growth expectations and retained earnings, which DDM ignores.
B12: CAPM | E12: =CAPM!I20 -> Regression Statistics
B13: =CAPM!C65 -> Monthly Rm (avg) | C13: =CAPM!E65 -> 0.011024713 | E13: =CAPM!I21 -> Multiple R | F13: =CAPM!J21 -> 0.41321227
B14: =CAPM!C65 -> Monthly Rm (avg) | C14: =CAPM!E65 -> 0.011024713 | E14: =CAPM!I22 -> R Square | F14: =CAPM!J22 -> 0.17074438
B15: =CAPM!C66 -> Annual Rm | C15: =CAPM!E66 -> 0.13229656 | E15: =CAPM!I23 -> Adjusted R Square | F15: =CAPM!J23 -> 0.15619604
B16: =CAPM!C67 -> Monthly Rf | C16: =CAPM!E67 -> 0.0055191667 | E16: =CAPM!I24 -> Standard Error | F16: =CAPM!J24 -> 0.21858626
B17: =CAPM!C68 -> Annual Rf | C17: =CAPM!E68 -> 0.06623 | E17: =CAPM!I25 -> Observations | F17: =CAPM!J25 -> 59
B18: =CAPM!C69 -> Beta | C18: =CAPM!E69 -> 2.7716321
B19: =CAPM!C70 -> ke (annual CAPM) | C19: =CAPM!E70 -> 0.2493422
B23: ='Adani Total Gas Stock Price His'!A3 -> Date | C23: ='Adani Total Gas Stock Price His'!B3 -> Price | D23: ='Adani Total Gas Stock Price His'!J3 -> Volume (Million) | E23: Year | F23: Price (Ave) | G23: Volume M (Ave) | I23: =CAPM!C1 -> Rm = Ln return | J23: =CAPM!D1 -> ATGL (Ri) | K23: =CAPM!E1 -> Rf =10yrs govt bond = 6.623% pa | L23: Stock excess return = Ri − Rf | M23: Market excess return = Rm − Rf
B24: ='Adani Total Gas Stock Price His'!A4 -> 45669 | C24: ='Adani Total Gas Stock Price His'!B4 -> 566.7 | D24: ='Adani Total Gas Stock Price His'!J4 -> 8510000 | E24: =AVERAGE(B24:B35) -> 45663.5 | F24: =AVERAGE(C24:C35) -> 615.66667 | G24: =AVERAGE(D24:D35) -> 27959167 | I24: =CAPM!C2 -> -0.0028032285 | J24: =CAPM!D2 -> -0.068121955 | K24: =CAPM!E2 -> 0.0055191667 | L24: =(J24-K24) -> -0.073641122 | M24: =(I24-K24) -> -0.0083223952
B25: ='Adani Total Gas Stock Price His'!A5 -> 45668 | C25: ='Adani Total Gas Stock Price His'!B5 -> 606.65 | D25: ='Adani Total Gas Stock Price His'!J5 -> 9690000 | E25: =AVERAGE(B36:B47) -> 45297.5 | F25: =AVERAGE(C36:C47) -> 886.09167 | G25: =AVERAGE(D36:D47) -> 49972500 | I25: =CAPM!C3 -> 0.018521455 | J25: =CAPM!D3 -> -0.040304264 | K25: =CAPM!E3 -> 0.0055191667 | L25: =(J25-K25) -> -0.045823431 | M25: =(I25-K25) -> 0.013002289
B26: ='Adani Total Gas Stock Price His'!A6 -> 45667 | C26: ='Adani Total Gas Stock Price His'!B6 -> 631.6 | D26: ='Adani Total Gas Stock Price His'!J6 -> 25150000 | E26: =AVERAGE(B48:B59) -> 44932.5 | F26: =AVERAGE(C48:C59) -> 841.00417 | G26: =AVERAGE(D48:D59) -> 39465833 | I26: =CAPM!C4 -> 0.044152984 | J26: =CAPM!D4 -> 0.010024748 | K26: =CAPM!E4 -> 0.0055191667 | L26: =(J26-K26) -> 0.0045055811 | M26: =(I26-K26) -> 0.038633817
B27: ='Adani Total Gas Stock Price His'!A7 -> 45666 | C27: ='Adani Total Gas Stock Price His'!B7 -> 625.3 | D27: ='Adani Total Gas Stock Price His'!J7 -> 97480000 | E27: =AVERAGE(B60:B71) -> 44567.5 | F27: =AVERAGE(C60:C71) -> 2828.4792 | G27: =AVERAGE(D60:D71) -> 7441666.7 | I27: =CAPM!C5 -> 0.0075146236 | J27: =CAPM!D5 -> 0.056246327 | K27: =CAPM!E5 -> 0.0055191667 | L27: =(J27-K27) -> 0.05072716 | M27: =(I27-K27) -> 0.0019954569
B28: ='Adani Total Gas Stock Price His'!A8 -> 45665 | C28: ='Adani Total Gas Stock Price His'!B8 -> 591.1 | D28: ='Adani Total Gas Stock Price His'!J8 -> 13650000 | E28: =AVERAGE(B72:B83) -> 44202.5 | F28: =AVERAGE(C72:C83) -> 1158.6042 | G28: =AVERAGE(D72:D83) -> 26290000 | I28: =CAPM!C6 -> -0.013883691 | J28: =CAPM!D6 -> -0.021754539 | K28: =CAPM!E6 -> 0.0055191667 | L28: =(J28-K28) -> -0.027273706 | M28: =(I28-K28) -> -0.019402858
B29: ='Adani Total Gas Stock Price His'!A9 -> 45664 | C29: ='Adani Total Gas Stock Price His'!B9 -> 604.1 | D29: ='Adani Total Gas Stock Price His'!J9 -> 12980000 | I29: =CAPM!C7 -> -0.029780228 | J29: =CAPM!D7 -> -0.11208344 | K29: =CAPM!E7 -> 0.0055191667 | L29: =(J29-K29) -> -0.1176026 | M29: =(I29-K29) -> -0.035299394
B30: ='Adani Total Gas Stock Price His'!A10 -> 45663 | C30: ='Adani Total Gas Stock Price His'!B10 -> 675.75 | D30: ='Adani Total Gas Stock Price His'!J10 -> 38140000 | I30: =CAPM!C8 -> 0.030493085 | J30: =CAPM!D8 -> -0.011769169 | K30: =CAPM!E8 -> 0.0055191667 | L30: =(J30-K30) -> -0.017288335 | M30: =(I30-K30) -> 0.024973918
B31: ='Adani Total Gas Stock Price His'!A11 -> 45662 | C31: ='Adani Total Gas Stock Price His'!B11 -> 683.75 | D31: ='Adani Total Gas Stock Price His'!J11 -> 40220000 | I31: =CAPM!C9 -> 0.016971003 | J31: =CAPM!D9 -> 0.13032942 | K31: =CAPM!E9 -> 0.0055191667 | L31: =(J31-K31) -> 0.12481025 | M31: =(I31-K31) -> 0.011451836
B32: ='Adani Total Gas Stock Price His'!A12 -> 45661 | C32: ='Adani Total Gas Stock Price His'!B12 -> 600.2 | D32: ='Adani Total Gas Stock Price His'!J12 -> 15130000 | I32: =CAPM!C10 -> 0.034059282 | J32: =CAPM!D10 -> -0.0039906937 | K32: =CAPM!E10 -> 0.0055191667 | L32: =(J32-K32) -> -0.0095098604 | M32: =(I32-K32) -> 0.028540115
B33: ='Adani Total Gas Stock Price His'!A13 -> 45660 | C33: ='Adani Total Gas Stock Price His'!B13 -> 602.6 | D33: ='Adani Total Gas Stock Price His'!J13 -> 25540000 | I33: =CAPM!C11 -> 0.061128855 | J33: =CAPM!D11 -> 0.078419123 | K33: =CAPM!E11 -> 0.0055191667 | L33: =(J33-K33) -> 0.072899957 | M33: =(I33-K33) -> 0.055609688
B34: ='Adani Total Gas Stock Price His'!A14 -> 45659 | C34: ='Adani Total Gas Stock Price His'!B14 -> 557.15 | D34: ='Adani Total Gas Stock Price His'!J14 -> 13700000 | I34: =CAPM!C12 -> -0.060663173 | J34: =CAPM!D12 -> -0.14346573 | K34: =CAPM!E12 -> 0.0055191667 | L34: =(J34-K34) -> -0.1489849 | M34: =(I34-K34) -> -0.066182339
B35: ='Adani Total Gas Stock Price His'!A15 -> 45658 | C35: ='Adani Total Gas Stock Price His'!B15 -> 643.1 | D35: ='Adani Total Gas Stock Price His'!J15 -> 35320000 | I35: =CAPM!C13 -> -0.0057854135 | J35: =CAPM!D13 -> -0.16839883 | K35: =CAPM!E13 -> 0.0055191667 | L35: =(J35-K35) -> -0.17391799 | M35: =(I35-K35) -> -0.01130458
B36: ='Adani Total Gas Stock Price His'!A16 -> 45303 | C36: ='Adani Total Gas Stock Price His'!B16 -> 761.05 | D36: ='Adani Total Gas Stock Price His'!J16 -> 37420000 | I36: =CAPM!C14 -> -0.020358247 | J36: =CAPM!D14 -> -0.065232223 | K36: =CAPM!E14 -> 0.0055191667 | L36: =(J36-K36) -> -0.07075139 | M36: =(I36-K36) -> -0.025877414
B37: ='Adani Total Gas Stock Price His'!A17 -> 45302 | C37: ='Adani Total Gas Stock Price His'!B17 -> 812.35 | D37: ='Adani Total Gas Stock Price His'!J17 -> 73230000 | I37: =CAPM!C15 -> -0.0030722181 | J37: =CAPM!D15 -> 0.12297437 | K37: =CAPM!E15 -> 0.0055191667 | L37: =(J37-K37) -> 0.1174552 | M37: =(I37-K37) -> -0.0085913848
B38: ='Adani Total Gas Stock Price His'!A18 -> 45301 | C38: ='Adani Total Gas Stock Price His'!B18 -> 718.35 | D38: ='Adani Total Gas Stock Price His'!J18 -> 14430000 | I38: =CAPM!C16 -> -0.064221263 | J38: =CAPM!D16 -> -0.090635807 | K38: =CAPM!E16 -> 0.0055191667 | L38: =(J38-K38) -> -0.096154974 | M38: =(I38-K38) -> -0.06974043 | O38: 5 Year | Y38: 3 Year
B39: ='Adani Total Gas Stock Price His'!A19 -> 45300 | C39: ='Adani Total Gas Stock Price His'!B19 -> 786.5 | D39: ='Adani Total Gas Stock Price His'!J19 -> 28750000 | I39: =CAPM!C17 -> 0.022527362 | J39: =CAPM!D17 -> -0.054254576 | K39: =CAPM!E17 -> 0.0055191667 | L39: =(J39-K39) -> -0.059773743 | M39: =(I39-K39) -> 0.017008196 | O39: SUMMARY OUTPUT | Y39: SUMMARY OUTPUT
B40: ='Adani Total Gas Stock Price His'!A20 -> 45299 | C40: ='Adani Total Gas Stock Price His'!B20 -> 830.35 | D40: ='Adani Total Gas Stock Price His'!J20 -> 82290000 | I40: =CAPM!C18 -> 0.011347671 | J40: =CAPM!D18 -> -0.075590756 | K40: =CAPM!E18 -> 0.0055191667 | L40: =(J40-K40) -> -0.081109923 | M40: =(I40-K40) -> 0.0058285039
B41: ='Adani Total Gas Stock Price His'!A21 -> 45298 | C41: ='Adani Total Gas Stock Price His'!B21 -> 895.55 | D41: ='Adani Total Gas Stock Price His'!J21 -> 45980000 | I41: =CAPM!C19 -> 0.038424514 | J41: =CAPM!D19 -> -0.0005023583 | K41: =CAPM!E19 -> 0.0055191667 | L41: =(J41-K41) -> -0.006021525 | M41: =(I41-K41) -> 0.032905347 | O41: Regression Statistics | Y41: Regression Statistics
B42: ='Adani Total Gas Stock Price His'!A22 -> 45297 | C42: ='Adani Total Gas Stock Price His'!B22 -> 896 | D42: ='Adani Total Gas Stock Price His'!J22 -> 50780000 | I42: =CAPM!C20 -> 0.063616576 | J42: =CAPM!D20 -> -0.14836228 | K42: =CAPM!E20 -> 0.0055191667 | L42: =(J42-K42) -> -0.15388144 | M42: =(I42-K42) -> 0.058097409 | O42: Multiple R | P42: 0.41321227 | Y42: Multiple R | Z42: 0.38432864
B43: ='Adani Total Gas Stock Price His'!A23 -> 45296 | C43: ='Adani Total Gas Stock Price His'!B23 -> 1039.3 | D43: ='Adani Total Gas Stock Price His'!J23 -> 45820000 | I43: =CAPM!C21 -> -0.0032856614 | J43: =CAPM!D21 -> 0.11208631 | K43: =CAPM!E21 -> 0.0055191667 | L43: =(J43-K43) -> 0.10656715 | M43: =(I43-K43) -> -0.008804828 | O43: R Square | P43: 0.17074438 | Y43: R Square | Z43: 0.14770851
B44: ='Adani Total Gas Stock Price His'!A24 -> 45295 | C44: ='Adani Total Gas Stock Price His'!B24 -> 929.1 | D44: ='Adani Total Gas Stock Price His'!J24 -> 26690000 | I44: =CAPM!C22 -> 0.012372256 | J44: =CAPM!D22 -> 0.0027483648 | K44: =CAPM!E22 -> 0.0055191667 | L44: =(J44-K44) -> -0.0027708018 | M44: =(I44-K44) -> 0.0068530888 | O44: Adjusted R Square | P44: 0.15619604 | Y44: Adjusted R Square | Z44: 0.12264111
B45: ='Adani Total Gas Stock Price His'!A25 -> 45294 | C45: ='Adani Total Gas Stock Price His'!B25 -> 926.55 | D45: ='Adani Total Gas Stock Price His'!J25 -> 59830000 | I45: =CAPM!C23 -> 0.0155319 | J45: =CAPM!D23 -> -0.10161383 | K45: =CAPM!E23 -> 0.0055191667 | L45: =(J45-K45) -> -0.10713299 | M45: =(I45-K45) -> 0.010012733 | O45: Standard Error | P45: 0.21858626 | Y45: Standard Error | Z45: 0.226321
B46: ='Adani Total Gas Stock Price His'!A26 -> 45293 | C46: ='Adani Total Gas Stock Price His'!B26 -> 1025.65 | D46: ='Adani Total Gas Stock Price His'!J26 -> 75130000 | I46: =CAPM!C24 -> 0.011764438 | J46: =CAPM!D24 -> 0.013052197 | K46: =CAPM!E24 -> 0.0055191667 | L46: =(J46-K46) -> 0.0075330304 | M46: =(I46-K46) -> 0.0062452712 | O46: Observations | P46: 59 | Y46: Observations | Z46: 36
...

Sheet DDM
B2: DDM for infinite period returns
B3: Value = PV of all any dividends + PV of the selling price
B4: This is also called the constant growth DDM
B5: Assumes an estimation of future dividend payment for an infinite period
B9: P0 | C9: D1 / (Ke-g)
B10: D1 = D0 X (1+g)
B11: Ke | C11: required return (CAPM output, annual)
B12: g | C12: growth rate (assume 0 because dividends constant)
B14: Label | C14: Value
B15: Latest Dividend (D₀) | C15: ='Dividend '!C3 -> 0.25 | D15: constant for last 5 years
B16: Growth Rate (g) | C16: 0 | D16: g = (Old Dividend / Latest Dividend ) - 1
B17: Next Dividend (D₁) | C17: =C15*(1+C16) -> 0.25 | D17: D1 = D0 X (1+g)
B18: Required Return (kₑ) | C18: =CAPM!E70 -> 0.2493422 | D18: CAPM output
B19: DDM Valuation: Price (P₀) | C19: =C17/(C18-C16) -> 1.0026381 | D19: P0 = D1 / (Ke-g)
B22: g ↓ \ kₑ → | C22: 20% | D22: 22% | E22: 24% | F22: 26% | G22: 28%
B23: 0 | C23: =$C$17/($C$22-$B23) -> 1.25 | D23: =$C$17/($D$22-$B23) -> 1.1363636 | E23: =$C$17/($E$22-$B23) -> 1.0416667 | F23: =$C$17/($F$22-$B23) -> 0.96153846 | G23: =$C$17/($G$22-$B23) -> 0.89285714
B24: 0.01 | C24: =$C$17/($C$22-$B24) -> 1.3157895 | D24: =$C$17/($D$22-$B24) -> 1.1904762 | E24: =$C$17/($E$22-$B24) -> 1.0869565 | F24: =$C$17/($F$22-$B24) -> 1 | G24: =$C$17/($G$22-$B24) -> 0.92592593
B25: 0.02 | C25: =$C$17/($C$22-$B25) -> 1.3888889 | D25: =$C$17/($D$22-$B25) -> 1.25 | E25: =$C$17/($E$22-$B25) -> 1.1363636 | F25: =$C$17/($F$22-$B25) -> 1.0416667 | G25: =$C$17/($G$22-$B25) -> 0.96153846
B26: 0.03 | C26: =$C$17/($C$22-$B26) -> 1.4705882 | D26: =$C$17/($D$22-$B26) -> 1.3157895 | E26: =$C$17/($E$22-$B26) -> 1.1904762 | F26: =$C$17/($F$22-$B26) -> 1.0869565 | G26: =$C$17/($G$22-$B26) -> 1
B27: 0.04 | C27: =$C$17/($C$22-$B27) -> 1.5625 | D27: =$C$17/($D$22-$B27) -> 1.3888889 | E27: =$C$17/($E$22-$B27) -> 1.25 | F27: =$C$17/($F$22-$B27) -> 1.1363636 | G27: =$C$17/($G$22-$B27) -> 1.0416667
B30: Interpret the Results
B31: Current Market Price: 564.15 INR (as of today’s close on 08Jan26).
B32: DDM Valuation: Base case (g = 0%, ke 24.93%) gives 1.00 INR, even optimistic scenarios (g = 4%, ke = 20%) only reach 1.563 INR.
B34: Observation:
B35: DDM valuation is far below the market price because Adani Total Gas pays negligible dividends (0.25 INR annually).
B36: DDM assumes value comes only from dividends, so it undervalues high-growth, low-dividend stocks.
B37: Market price reflects growth expectations and retained earnings, which DDM ignores.

Sheet CAPM
A1: Date | B1: Price | C1: Rm = Ln return | D1: ATGL (Ri) | E1: Rf =10yrs govt bond = 6.623% pa | F1: Er = Rf+(Rm-Rf)*Beta
A2: 45669 | B2: ='Nifty 50 Historical Data'!B4 -> 26129.6 | C2: =LN(B2/B3) -> -0.0028032285 | D2: ='Monthly Vs Risk'!D2 -> -0.068121955 | E2: =Reference!$B$4%/12 -> 0.0055191667 | F2: =E2+(C2-E2)*$J$35 -> -0.017547451 | I2: Definitions
A3: 45668 | B3: ='Nifty 50 Historical Data'!B5 -> 26202.95 | C3: =LN(B3/B4) -> 0.018521455 | D3: ='Monthly Vs Risk'!D3 -> -0.040304264 | E3: =Reference!$B$4%/12 -> 0.0055191667 | F3: =E3+(C3-E3)*$J$35 -> 0.041556727 | I3: CAPM = Er=Rf+(Rm-Rf)Beta
A4: 45667 | B4: ='Nifty 50 Historical Data'!B6 -> 25722.1 | C4: =LN(B4/B5) -> 0.044152984 | D4: ='Monthly Vs Risk'!D4 -> 0.010024748 | E4: =Reference!$B$4%/12 -> 0.0055191667 | F4: =E4+(C4-E4)*$J$35 -> 0.11259789 | I4: Er | J4: Expected return | M4: 10 years govt. bonds rate
A5: 45666 | B5: ='Nifty 50 Historical Data'!B7 -> 24611.1 | C5: =LN(B5/B6) -> 0.0075146236 | D5: ='Monthly Vs Risk'!D5 -> 0.056246327 | E5: =Reference!$B$4%/12 -> 0.0055191667 | F5: =E5+(C5-E5)*$J$35 -> 0.011049839 | I5: Rf | J5: Risk free rate of return
A6: 45665 | B6: ='Nifty 50 Historical Data'!B8 -> 24426.85 | C6: =LN(B6/B7) -> -0.013883691 | D6: ='Monthly Vs Risk'!D6 -> -0.021754539 | E6: =Reference!$B$4%/12 -> 0.0055191667 | F6: =E6+(C6-E6)*$J$35 -> -0.048258417 | I6: Rm | J6: Market return (index rate of return)
A7: 45664 | B7: ='Nifty 50 Historical Data'!B9 -> 24768.35 | C7: =LN(B7/B8) -> -0.029780228 | D7: ='Monthly Vs Risk'!D7 -> -0.11208344 | E7: =Reference!$B$4%/12 -> 0.0055191667 | F7: =E7+(C7-E7)*$J$35 -> -0.092317767 | I7: Rm-Rf | J7: Risk premium | L7: =J35 -> 2.7716321
A8: 45663 | B8: ='Nifty 50 Historical Data'!B10 -> 25517.05 | C8: =LN(B8/B9) -> 0.030493085 | D8: ='Monthly Vs Risk'!D8 -> -0.011769169 | E8: =Reference!$B$4%/12 -> 0.0055191667 | F8: =E8+(C8-E8)*$J$35 -> 0.074737679 | I8: Beta | J8: Equity coefficient
A9: 45662 | B9: ='Nifty 50 Historical Data'!B11 -> 24750.7 | C9: =LN(B9/B10) -> 0.016971003 | D9: ='Monthly Vs Risk'!D9 -> 0.13032942 | E9: =Reference!$B$4%/12 -> 0.0055191667 | F9: =E9+(C9-E9)*$J$35 -> 0.037259444 | I9: Linear Reggression = Y = a+bx
A10: 45661 | B10: ='Nifty 50 Historical Data'!B12 -> 24334.2 | C10: =LN(B10/B11) -> 0.034059282 | D10: ='Monthly Vs Risk'!D10 -> -0.0039906937 | E10: =Reference!$B$4%/12 -> 0.0055191667 | F10: =E10+(C10-E10)*$J$35 -> 0.084621865
A11: 45660 | B11: ='Nifty 50 Historical Data'!B13 -> 23519.35 | C11: =LN(B11/B12) -> 0.061128855 | D11: ='Monthly Vs Risk'!D11 -> 0.078419123 | E11: =Reference!$B$4%/12 -> 0.0055191667 | F11: =E11+(C11-E11)*$J$35 -> 0.15964876
A12: 45659 | B12: ='Nifty 50 Historical Data'!B14 -> 22124.7 | C12: =LN(B12/B13) -> -0.060663173 | D12: ='Monthly Vs Risk'!D12 -> -0.14346573 | E12: =Reference!$B$4%/12 -> 0.0055191667 | F12: =E12+(C12-E12)*$J$35 -> -0.17791393
A13: 45658 | B13: ='Nifty 50 Historical Data'!B15 -> 23508.4 | C13: =LN(B13/B14) -> -0.0057854135 | D13: ='Monthly Vs Risk'!D13 -> -0.16839883 | E13: =Reference!$B$4%/12 -> 0.0055191667 | F13: =E13+(C13-E13)*$J$35 -> -0.02581297
A14: 45303 | B14: ='Nifty 50 Historical Data'!B16 -> 23644.8 | C14: =LN(B14/B15) -> -0.020358247 | D14: ='Monthly Vs Risk'!D14 -> -0.065232223 | E14: =Reference!$B$4%/12 -> 0.0055191667 | F14: =E14+(C14-E14)*$J$35 -> -0.066203504 | G14: kk
A15: 45302 | B15: ='Nifty 50 Historical Data'!B17 -> 24131.1 | C15: =LN(B15/B16) -> -0.0030722181 | D15: ='Monthly Vs Risk'!D15 -> 0.12297437 | E15: =Reference!$B$4%/12 -> 0.0055191667 | F15: =E15+(C15-E15)*$J$35 -> -0.018292991
A16: 45301 | B16: ='Nifty 50 Historical Data'!B18 -> 24205.35 | C16: =LN(B16/B17) -> -0.064221263 | D16: ='Monthly Vs Risk'!D16 -> -0.090635807 | E16: =Reference!$B$4%/12 -> 0.0055191667 | F16: =E16+(C16-E16)*$J$35 -> -0.18777565
A17: 45300 | B17: ='Nifty 50 Historical Data'!B19 -> 25810.85 | C17: =LN(B17/B18) -> 0.022527362 | D17: ='Monthly Vs Risk'!D17 -> -0.054254576 | E17: =Reference!$B$4%/12 -> 0.0055191667 | F17: =E17+(C17-E17)*$J$35 -> 0.052659627
A18: 45299 | B18: ='Nifty 50 Historical Data'!B20 -> 25235.9 | C18: =LN(B18/B19) -> 0.011347671 | D18: ='Monthly Vs Risk'!D18 -> -0.075590756 | E18: =Reference!$B$4%/12 -> 0.0055191667 | F18: =E18+(C18-E18)*$J$35 -> 0.021673635
A19: 45298 | B19: ='Nifty 50 Historical Data'!B21 -> 24951.15 | C19: =LN(B19/B20) -> 0.038424514 | D19: ='Monthly Vs Risk'!D19 -> -0.0005023583 | E19: =Reference!$B$4%/12 -> 0.0055191667 | F19: =E19+(C19-E19)*$J$35 -> 0.096720682
A20: 45297 | B20: ='Nifty 50 Historical Data'!B22 -> 24010.6 | C20: =LN(B20/B21) -> 0.063616576 | D20: ='Monthly Vs Risk'!D20 -> -0.14836228 | E20: =Reference!$B$4%/12 -> 0.0055191667 | F20: =E20+(C20-E20)*$J$35 -> 0.16654381 | I20: Regression Statistics
A21: 45296 | B21: ='Nifty 50 Historical Data'!B23 -> 22530.7 | C21: =LN(B21/B22) -> -0.0032856614 | D21: ='Monthly Vs Risk'!D21 -> 0.11208631 | E21: =Reference!$B$4%/12 -> 0.0055191667 | F21: =E21+(C21-E21)*$J$35 -> -0.018884577 | I21: Multiple R | J21: 0.41321227
A22: 45295 | B22: ='Nifty 50 Historical Data'!B24 -> 22604.85 | C22: =LN(B22/B23) -> 0.012372256 | D22: ='Monthly Vs Risk'!D22 -> 0.0027483648 | E22: =Reference!$B$4%/12 -> 0.0055191667 | F22: =E22+(C22-E22)*$J$35 -> 0.024513407 | I22: R Square | J22: 0.17074438
A23: 45294 | B23: ='Nifty 50 Historical Data'!B25 -> 22326.9 | C23: =LN(B23/B24) -> 0.0155319 | D23: ='Monthly Vs Risk'!D23 -> -0.10161383 | E23: =Reference!$B$4%/12 -> 0.0055191667 | F23: =E23+(C23-E23)*$J$35 -> 0.03327078 | I23: Adjusted R Square | J23: 0.15619604
A24: 45293 | B24: ='Nifty 50 Historical Data'!B26 -> 21982.8 | C24: =LN(B24/B25) -> 0.011764438 | D24: ='Monthly Vs Risk'!D24 -> 0.013052197 | E24: =Reference!$B$4%/12 -> 0.0055191667 | F24: =E24+(C24-E24)*$J$35 -> 0.022828761 | I24: Standard Error | J24: 0.21858626
A25: 45292 | B25: ='Nifty 50 Historical Data'!B27 -> 21725.7 | C25: =LN(B25/B26) -> -0.00026232768 | D25: ='Monthly Vs Risk'!D25 -> 0.024397551 | E25: =Reference!$B$4%/12 -> 0.0055191667 | F25: =E25+(C25-E25)*$J$35 -> -0.010505008 | I25: Observations | J25: 59
A26: 44938 | B26: ='Nifty 50 Historical Data'!B28 -> 21731.4 | C26: =LN(B26/B27) -> 0.076390509 | D26: ='Monthly Vs Risk'!D26 -> 0.33205869 | E26: =Reference!$B$4%/12 -> 0.0055191667 | F26: =E26+(C26-E26)*$J$35 -> 0.20194845
A27: 44937 | B27: ='Nifty 50 Historical Data'!B29 -> 20133.15 | C27: =LN(B27/B28) -> 0.053748009 | D27: ='Monthly Vs Risk'!D27 -> 0.22798737 | E27: =Reference!$B$4%/12 -> 0.0055191667 | F27: =E27+(C27-E27)*$J$35 -> 0.13919177 | I27: ANOVA
A28: 44936 | B28: ='Nifty 50 Historical Data'!B30 -> 19079.6 | C28: =LN(B28/B29) -> -0.02886204 | D28: ='Monthly Vs Risk'!D28 -> -0.083186658 | E28: =Reference!$B$4%/12 -> 0.0055191667 | F28: =E28+(C28-E28)*$J$35 -> -0.089772888 | J28: df | K28: SS | L28: MS | M28: F | N28: Significance F
A29: 44935 | B29: ='Nifty 50 Historical Data'!B31 -> 19638.3 | C29: =LN(B29/B30) -> 0.019773297 | D29: ='Monthly Vs Risk'!D29 -> -0.036111365 | E29: =Reference!$B$4%/12 -> 0.0055191667 | F29: =E29+(C29-E29)*$J$35 -> 0.045026372 | I29: Regression | J29: 1 | K29: 0.560762 | L29: 0.560762 | M29: 11.736345 | N29: 0.0011430593
A30: 44934 | B30: ='Nifty 50 Historical Data'!B32 -> 19253.8 | C30: =LN(B30/B31) -> -0.025637434 | D30: ='Monthly Vs Risk'!D30 -> -0.042946192 | E30: =Reference!$B$4%/12 -> 0.0055191667 | F30: =E30+(C30-E30)*$J$35 -> -0.080835467 | I30: Residual | J30: 57 | K30: 2.7234573 | L30: 0.047779953
A31: 44933 | B31: ='Nifty 50 Historical Data'!B33 -> 19753.8 | C31: =LN(B31/B32) -> 0.029006074 | D31: ='Monthly Vs Risk'!D31 -> 0.013805878 | E31: =Reference!$B$4%/12 -> 0.0055191667 | F31: =E31+(C31-E31)*$J$35 -> 0.070616233 | I31: Total | J31: 58 | K31: 3.2842193
A32: 44932 | B32: ='Nifty 50 Historical Data'!B34 -> 19189.05 | C32: =LN(B32/B33) -> 0.034711339 | D32: ='Monthly Vs Risk'!D32 -> -0.014483666 | E32: =Reference!$B$4%/12 -> 0.0055191667 | F32: =E32+(C32-E32)*$J$35 -> 0.086429128
A33: 44931 | B33: ='Nifty 50 Historical Data'!B35 -> 18534.4 | C33: =LN(B33/B34) -> 0.0256521 | D33: ='Monthly Vs Risk'!D33 -> -0.3526769 | E33: =Reference!$B$4%/12 -> 0.0055191667 | F33: =E33+(C33-E33)*$J$35 -> 0.061320251 | J33: Coefficients | K33: Standard Error | L33: t Stat | M33: P-value | N33: Lower 95% | O33: Upper 95% | P33: Lower 95.0% | Q33: Upper 95.0%
A34: 44930 | B34: ='Nifty 50 Historical Data'!B36 -> 18065 | C34: =LN(B34/B35) -> 0.039822056 | D34: ='Monthly Vs Risk'!D34 -> 0.085281273 | E34: =Reference!$B$4%/12 -> 0.0055191667 | F34: =E34+(C34-E34)*$J$35 -> 0.10059416 | I34: Intercept | J34: -0.02382934 | K34: 0.02982257 | L34: -0.79903709 | M34: 0.42758597 | N34: -0.083548007 | O34: 0.035889327 | P34: -0.083548007 | Q34: 0.035889327
A35: 44929 | B35: ='Nifty 50 Historical Data'!B37 -> 17359.75 | C35: =LN(B35/B36) -> 0.0032195091 | D35: ='Monthly Vs Risk'!D35 -> 0.24594549 | E35: =Reference!$B$4%/12 -> 0.0055191667 | F35: =E35+(C35-E35)*$J$35 -> -0.0008546381 | I35: Beta | J35: 2.7716321 | K35: 0.80903842 | L35: 3.4258349 | M35: 0.0011430593 | N35: 1.1515606 | O35: 4.3917036 | P35: 1.1515606 | Q35: 4.3917036
A36: 44928 | B36: ='Nifty 50 Historical Data'!B38 -> 17303.95 | C36: =LN(B36/B37) -> -0.020489133 | D36: ='Monthly Vs Risk'!D36 -> -1.1336316 | E36: =Reference!$B$4%/12 -> 0.0055191667 | F36: =E36+(C36-E36)*$J$35 -> -0.06656627
A37: 44927 | B37: ='Nifty 50 Historical Data'!B39 -> 17662.15 | C37: =LN(B37/B38) -> -0.024780781 | D37: ='Monthly Vs Risk'!D37 -> -0.56056401 | E37: =Reference!$B$4%/12 -> 0.0055191667 | F37: =E37+(C37-E37)*$J$35 -> -0.078461141
A38: 44573 | B38: ='Nifty 50 Historical Data'!B40 -> 18105.3 | C38: =LN(B38/B39) -> -0.035434274 | D38: ='Monthly Vs Risk'!D38 -> 0.01640858 | E38: =Reference!$B$4%/12 -> 0.0055191667 | F38: =E38+(C38-E38)*$J$35 -> -0.1079887
A39: 44572 | B39: ='Nifty 50 Historical Data'!B41 -> 18758.35 | C39: =LN(B39/B40) -> 0.040589681 | D39: ='Monthly Vs Risk'!D39 -> 0.0082647383 | E39: =Reference!$B$4%/12 -> 0.0055191667 | F39: =E39+(C39-E39)*$J$35 -> 0.10272173 | I39: RESIDUAL OUTPUT
A40: 44571 | B40: ='Nifty 50 Historical Data'!B42 -> 18012.2 | C40: =LN(B40/B41) -> 0.052301307 | D40: ='Monthly Vs Risk'!D40 -> 0.075799303 | E40: =Reference!$B$4%/12 -> 0.0055191667 | F40: =E40+(C40-E40)*$J$35 -> 0.13518205
...

Sheet Monthly Vs Risk
A1: Date | B1: ATGL (Monthly) | C1: Simple Return (Ri) =[ Pt-P(t-1)/P(t-1)] | D1: Ri=Lognormal formula: LN(Pt/P(t-1) | E1: Add 10 | F1: Probability (Pi) | G1: Er = Sum of ( Ri*Pi) | H1: Variance= (Ri-Er)^2)*Pi
A2: 45669 | B2: ='Adani Total Gas Stock Price His'!B4 -> 566.7 | C2: =(B2-B3)/B3 -> -0.065853458 | D2: =LN(B2/B3) -> -0.068121955 | E2: =10+D2 -> 9.931878 | F2: =1/59 -> 0.016949153 | G2: =D2*F2 -> -0.0011546094 | H2: =(D2-$G$66)^2*F2 -> 9.4955636e-05
A3: 45668 | B3: ='Adani Total Gas Stock Price His'!B5 -> 606.65 | C3: =(B3-B4)/B4 -> -0.03950285 | D3: =LN(B3/B4) -> -0.040304264 | E3: =10+D3 -> 9.9596957 | F3: =1/59 -> 0.016949153 | G3: =D3*F3 -> -0.00068312312 | H3: =(D3-$G$66)^2*F3 -> 3.7490679e-05
A4: 45667 | B4: ='Adani Total Gas Stock Price His'!B6 -> 631.6 | C4: =(B4-B5)/B5 -> 0.010075164 | D4: =LN(B4/B5) -> 0.010024748 | E4: =10+D4 -> 10.010025 | F4: =1/59 -> 0.016949153 | G4: =D4*F4 -> 0.00016991098 | H4: =(D4-$G$66)^2*F4 -> 1.8431217e-07
A5: 45666 | B5: ='Adani Total Gas Stock Price His'!B7 -> 625.3 | C5: =(B5-B6)/B6 -> 0.05785823 | D5: =LN(B5/B6) -> 0.056246327 | E5: =10+D5 -> 10.056246 | F5: =1/59 -> 0.016949153 | G5: =D5*F5 -> 0.00095332757 | H5: =(D5-$G$66)^2*F5 -> 4.1561913e-05
A6: 45665 | B6: ='Adani Total Gas Stock Price His'!B8 -> 591.1 | C6: =(B6-B7)/B7 -> -0.021519616 | D6: =LN(B6/B7) -> -0.021754539 | E6: =10+D6 -> 9.9782455 | F6: =1/59 -> 0.016949153 | G6: =D6*F6 -> -0.00036872101 | H6: =(D6-$G$66)^2*F6 -> 1.3749226e-05
A7: 45664 | B7: ='Adani Total Gas Stock Price His'!B9 -> 604.1 | C7: =(B7-B8)/B8 -> -0.10603034 | D7: =LN(B7/B8) -> -0.11208344 | E7: =10+D7 -> 9.8879166 | F7: =1/59 -> 0.016949153 | G7: =D7*F7 -> -0.0018997193 | H7: =(D7-$G$66)^2*F7 -> 0.00023925333
A8: 45663 | B8: ='Adani Total Gas Stock Price His'!B10 -> 675.75 | C8: =(B8-B9)/B9 -> -0.011700183 | D8: =LN(B8/B9) -> -0.011769169 | E8: =10+D8 -> 9.9882308 | F8: =1/59 -> 0.016949153 | G8: =D8*F8 -> -0.00019947743 | H8: =(D8-$G$66)^2*F8 -> 5.7985136e-06
A9: 45662 | B9: ='Adani Total Gas Stock Price His'!B11 -> 683.75 | C9: =(B9-B10)/B10 -> 0.1392036 | D9: =LN(B9/B10) -> 0.13032942 | E9: =10+D9 -> 10.130329 | F9: =1/59 -> 0.016949153 | G9: =D9*F9 -> 0.0022089732 | H9: =(D9-$G$66)^2*F9 -> 0.00025894121
A10: 45661 | B10: ='Adani Total Gas Stock Price His'!B12 -> 600.2 | C10: =(B10-B11)/B11 -> -0.0039827415 | D10: =LN(B10/B11) -> -0.0039906937 | E10: =10+D10 -> 9.9960093 | F10: =1/59 -> 0.016949153 | G10: =D10*F10 -> -6.7638876e-05 | H10: =(D10-$G$66)^2*F10 -> 1.9469713e-06
A11: 45660 | B11: ='Adani Total Gas Stock Price His'!B13 -> 602.6 | C11: =(B11-B12)/B12 -> 0.081575877 | D11: =LN(B11/B12) -> 0.078419123 | E11: =10+D11 -> 10.078419 | F11: =1/59 -> 0.016949153 | G11: =D11*F11 -> 0.0013291377 | H11: =(D11-$G$66)^2*F11 -> 8.7114319e-05
A12: 45659 | B12: ='Adani Total Gas Stock Price His'!B14 -> 557.15 | C12: =(B12-B13)/B13 -> -0.13364951 | D12: =LN(B12/B13) -> -0.14346573 | E12: =10+D12 -> 9.8565343 | F12: =1/59 -> 0.016949153 | G12: =D12*F12 -> -0.0024316225 | H12: =(D12-$G$66)^2*F12 -> 0.0003823371
A13: 45658 | B13: ='Adani Total Gas Stock Price His'!B15 -> 643.1 | C13: =(B13-B14)/B14 -> -0.15498325 | D13: =LN(B13/B14) -> -0.16839883 | E13: =10+D13 -> 9.8316012 | F13: =1/59 -> 0.016949153 | G13: =D13*F13 -> -0.0028542174 | H13: =(D13-$G$66)^2*F13 -> 0.00051981514
... A60: 44198 | B60: ='Adani Total Gas Stock Price His'!B62 -> 512.2 | C60: =(B60-B61)/B61 -> 0.34418055 | D60: =LN(B60/B61) -> 0.29578457 | E60: =10+D60 -> 10.295785 | F60: =1/59 -> 0.016949153 | G60: =D60*F60 -> 0.0050132979 | H60: =(D60-$G$66)^2*F60 -> 0.0014161732
A61: 44197 | B61: ='Adani Total Gas Stock Price His'!B63 -> 381.05
A63: Count | B63: =COUNT(B2:B61) -> 60 | C63: =COUNT(C2:C61) -> 59 | D63: =COUNT(D2:D61) -> 59
A64: 1 | B64: ARM (Monthly) | C64: =AVEDEV(C2:C60) -> 0.14819556 | D64: =AVEDEV(D2:D60) -> 0.14363625
A65: 2 | B65: GM (Monthly) | C65: =GEOMEAN(E2:E60) -> 10.003866 | D65: =C65-10 -> 0.0038656469
A66: 3 | B66: Expected Return | C66: sum of (Ri*Pi) | G66: =SUM(G2:G60) -> 0.0067271095
A67: 4 | B67: Variance = sum of[(Ri-ER)^2*Pi] | H67: =SUM(H2:H60) -> 0.055664734
A68: 5 | B68: Risk (volatility of not achieving expected return) | C68: sqtr of Variance | H68: =SQRT(H67) -> 0.23593375 | I68: =H68*SQRT(12) -> 0.81729848
A69: 6 | B69: Coefficient of Cor | C69: =_xlfn.COVARIANCE.S(#REF!,#REF!) -> #REF!
A72: Stock Price Prediction based on return
A73: 46030 | B73: =B2*(1+D65) -> 568.89066 | C73: =B2*(1+D64) -> 648.09866
A75: Stock price prediction based on risk and return
A76: 46030 | B76: =(B2*(1+G66)) -> 570.51225
B77: =B76*H68 -> 134.60309
B78: =B76-B77 -> 435.90916
A79: Price Rang | B79: between 570.512 to 435.909

Sheet Dividend 
B2: Ex-Dividend Date | C2: Dividend | D2: Type | E2: Payment Date | F2: Yield
B3: Jun 13, 2025 | C3: 0.25 | D3: 12M | E3: Jul 25, 2025 | F3: 0.0004
B4: Jun 14, 2024 | C4: 0.25 | D4: 12M | E4: Jul 25, 2024 | F4: 0.0003
B5: Jul 07, 2023 | C5: 0.25 | D5: 12M | E5: Aug 17, 2023 | F5: 0.0004
B6: Jul 14, 2022 | C6: 0.25 | D6: 12M | E6: Aug 25, 2022 | F6: 0.0001
B7: Jun 24, 2021 | C7: 0.25 | D7: 12M | E7: Aug 11, 2021 | F7: 0.0002
B8: Mar 26, 2020 | C8: 0.25 | D8: I | E8: Apr 18, 2020 | F8: 0.0059
B9: Jul 26, 2019 | C9: 0.25 | D9: 12M | E9: Sep 05, 2019 | F9: 0.0016
B11: GM | C11: =GEOMEAN(Table2[Dividend]) -> 0.25

Sheet Adani Total Gas Stock Price His
A1: Data Source | C1: https://www.investing.com/equities/adani-gas
A2: Data Downloaded | C2: 46027
A3: Date | B3: Price | C3: Open | D3: High | E3: Low | F3: Vol. | G3: Change % | I3: Volume (Million) | J3: Volume (Million)
A4: 45669 | B4: 566.7 | C4: 609.05 | D4: 610.9 | E4: 561 | F4: 8.51M | G4: -0.0659 | I4: =_xlfn.TEXTBEFORE(F4,"M") -> 8.51 | J4: =I4*1000000 -> 8510000
A5: 45668 | B5: 606.65 | C5: 631.6 | D5: 634.9 | E5: 599.05 | F5: 9.69M | G5: -0.0395 | I5: =_xlfn.TEXTBEFORE(F5,"M") -> 9.69 | J5: =I5*1000000 -> 9690000
A6: 45667 | B6: 631.6 | C6: 630.05 | D6: 675 | E6: 613.55 | F6: 25.15M | G6: 0.0101 | I6: =_xlfn.TEXTBEFORE(F6,"M") -> 25.15 | J6: =I6*1000000 -> 25150000
A7: 45666 | B7: 625.3 | C7: 593.9 | D7: 798 | E7: 588.2 | F7: 97.48M | G7: 0.0579 | I7: =_xlfn.TEXTBEFORE(F7,"M") -> 97.48 | J7: =I7*1000000 -> 97480000
A8: 45665 | B8: 591.1 | C8: 617 | D8: 644.5 | E8: 577.1 | F8: 13.65M | G8: -0.0215 | I8: =_xlfn.TEXTBEFORE(F8,"M") -> 13.65 | J8: =I8*1000000 -> 13650000
A9: 45664 | B9: 604.1 | C9: 677 | D9: 684 | E9: 602.45 | F9: 12.98M | G9: -0.106 | I9: =_xlfn.TEXTBEFORE(F9,"M") -> 12.98 | J9: =I9*1000000 -> 12980000
A10: 45663 | B10: 675.75 | C10: 685 | D10: 721 | E10: 608.15 | F10: 38.14M | G10: -0.0117 | I10: =_xlfn.TEXTBEFORE(F10,"M") -> 38.14 | J10: =I10*1000000 -> 38140000
A11: 45662 | B11: 683.75 | C11: 599 | D11: 693 | E11: 587.1 | F11: 40.22M | G11: 0.1392 | I11: =_xlfn.TEXTBEFORE(F11,"M") -> 40.22 | J11: =I11*1000000 -> 40220000
A12: 45661 | B12: 600.2 | C12: 599.05 | D12: 634 | E12: 545.5 | F12: 15.13M | G12: -0.004 | I12: =_xlfn.TEXTBEFORE(F12,"M") -> 15.13 | J12: =I12*1000000 -> 15130000
A13: 45660 | B13: 602.6 | C13: 559.4 | D13: 641.9 | E13: 532.6 | F13: 25.54M | G13: 0.0816 | I13: =_xlfn.TEXTBEFORE(F13,"M") -> 25.54 | J13: =I13*1000000 -> 25540000
A14: 45659 | B14: 557.15 | C14: 647.5 | D14: 654.4 | E14: 555 | F14: 13.70M | G14: -0.1336 | I14: =_xlfn.TEXTBEFORE(F14,"M") -> 13.70 | J14: =I14*1000000 -> 13700000
A15: 45658 | B15: 643.1 | C15: 751 | D15: 766.6 | E15: 607.4 | F15: 35.32M | G15: -0.155 | I15: =_xlfn.TEXTBEFORE(F15,"M") -> 35.32 | J15: =I15*1000000 -> 35320000
... A63: 44197 | B63: 381.05 | C63: 377.4 | D63: 389.4 | E63: 341 | F63: 23.51M | G63: 0.0145 | I63: =_xlfn.TEXTBEFORE(F63,"M") -> 23.51 | J63: =I63*1000000 -> 23510000

Sheet Nifty 50 Historical Data
A1: Data Source | C1: https://www.investing.com/equities/adani-gas
A2: Data Downloaded | C2: 46027
A3: Date | B3: Price | C3: Open | D3: High | E3: Low | F3: Vol. | G3: Change %
A4: 45669 | B4: 26129.6 | C4: 26325.8 | D4: 26325.8 | E4: 25693.25 | F4: 5.37B | G4: -0.0028
A5: 45668 | B5: 26202.95 | C5: 25696.85 | D5: 26310.45 | E5: 25318.45 | F5: 5.50B | G5: 0.0187
A6: 45667 | B6: 25722.1 | C6: 24620.55 | D6: 26104.2 | E6: 24605.95 | F6: 6.24B | G6: 0.0451
A7: 45666 | B7: 24611.1 | C7: 24432.7 | D7: 25448.95 | E7: 24432.7 | F7: 5.98B | G7: 0.0075
A8: 45665 | B8: 24426.85 | C8: 24734.9 | D8: 25153.65 | E8: 24337.5 | F8: 5.87B | G8: -0.0138
A9: 45664 | B9: 24768.35 | C9: 25551.35 | D9: 25608.1 | E9: 24598.6 | F9: 6.28B | G9: -0.0293
A10: 45663 | B10: 25517.05 | C10: 24669.7 | D10: 25669.35 | E10: 24473 | F10: 7.06B | G10: 0.031
A11: 45662 | B11: 24750.7 | C11: 24311.9 | D11: 25116.25 | E11: 23935.75 | F11: 8.55B | G11: 0.0171
A12: 45661 | B12: 24334.2 | C12: 23341.1 | D12: 24457.65 | E12: 21743.65 | F12: 7.66B | G12: 0.0346
A13: 45660 | B13: 23519.35 | C13: 22194.55 | D13: 23869.6 | E13: 21964.6 | F13: 6.24B | G13: 0.063
A14: 45659 | B14: 22124.7 | C14: 23528.6 | D14: 23807.3 | E14: 22104.85 | F14: 5.65B | G14: -0.0589
A15: 45658 | B15: 23508.4 | C15: 23637.65 | D15: 24226.7 | E15: 22786.9 | F15: 6.46B | G15: -0.0058
... A63: 44197 | B63: 13634.6 | C63: 13996.1 | D63: 14753.55 | E63: 13596.75 | F63: 13.02B | G63: -0.0248

Sheet Reference
A1: References used to perform the task in tis file
A3: 46030 | B3: https://tradingeconomics.com/india/government-bond-yield
A4: India 10Y Bond Yield | B4: 6.623
