Workbook

Sheet Assignment
B2: Course | C2: MBA in AI for business
B3: Course code | C3: S1-25_MBACCZG521
B4: FM ASSIGNMENT | C4: Equity Research Report
B7: Name | C7: Bits id | D7: Discription
B8: AKHILESH PANDAY | C8: 2024BC26663
B10: Financial Ratio
B11: Profitability Ratios
B12: Turnover Ratio/Efficiency Ratios
B13: Solvency Ratios
B14: Market / Valuation Ratios
B15: Liquidity Ratios

Sheet ATGL_Finanacial Ratios
B1: Adani Total Gas Ltd.
B2: Performance Period | C2: Mar'18 | D2: Mar'19 | E2: Mar'20 | F2: Mar'21 | G2: Mar'22 | H2: Mar'23 | I2: Mar'24 | J2: Mar'25
B3: Liquidity Ratio
B4: CURRENT RATIO = Current Assets/Current Liability | C4: =C5/C6 -> 1.7884615 | D4: =D5/D6 -> 1.3699187 | E4: =E5/E6 -> 0.94416244 | F4: =F5/F6 -> 0.2759901 | G4: =G5/G6 -> 0.24726776 | H4: =H5/H6 -> 0.39124487 | I4: =I5/I6 -> 0.56985091 | J4: =J5/J6 -> 0.72886866
B5: Current Assets | C5: =ATFL_BS_Consolidated!D39 -> 651 | D5: =ATFL_BS_Consolidated!E39 -> 674 | E5: =ATFL_BS_Consolidated!F39 -> 558 | F5: =ATFL_BS_Consolidated!G39 -> 223 | G5: =ATFL_BS_Consolidated!H39 -> 362 | H5: =ATFL_BS_Consolidated!I39 -> 858 | I5: =ATFL_BS_Consolidated!J39 -> 1032 | J5: =ATFL_BS_Consolidated!K39 -> 1121
B6: Current Liability | C6: =ATFL_BS_Consolidated!D75 -> 364 | D6: =ATFL_BS_Consolidated!E75 -> 492 | E6: =ATFL_BS_Consolidated!F75 -> 591 | F6: =ATFL_BS_Consolidated!G75 -> 808 | G6: =ATFL_BS_Consolidated!H75 -> 1464 | H6: =ATFL_BS_Consolidated!I75 -> 2193 | I6: =ATFL_BS_Consolidated!J75 -> 1811 | J6: =ATFL_BS_Consolidated!K75 -> 1538
B7: QUICK RATIO = QuiCK Asset/Current Liability | C7: =C8/C6 -> 1.6726374 | D7: =D8/D6 -> 1.2805691 | E7: =E8/E6 -> 0.87428088 | F7: =F8/F6 -> 0.21162129 | G7: =G8/G6 -> 0.1948224 | H7: =H8/H6 -> 0.34976744 | I7: =I8/I6 -> 0.51509111 | J7: =J8/J6 -> 0.65344603
B8: Quick Asset | C8: =ATFL_BS_Consolidated!D39-ATFL_BS_Consolidated!D41 -> 608.84 | D8: =ATFL_BS_Consolidated!E39-ATFL_BS_Consolidated!E41 -> 630.04 | E8: =ATFL_BS_Consolidated!F39-ATFL_BS_Consolidated!F41 -> 516.7 | F8: =ATFL_BS_Consolidated!G39-ATFL_BS_Consolidated!G41 -> 170.99 | G8: =ATFL_BS_Consolidated!H39-ATFL_BS_Consolidated!H41 -> 285.22 | H8: =ATFL_BS_Consolidated!I39-ATFL_BS_Consolidated!I41 -> 767.04 | I8: =ATFL_BS_Consolidated!J39-ATFL_BS_Consolidated!J41 -> 932.83 | J8: =ATFL_BS_Consolidated!K39-ATFL_BS_Consolidated!K41 -> 1005
B9: ABSOLUTE LIQUID RATIO= CASH+BANK+CI+MS/Current Liability | C9: =C10/C6 -> 0.24651099 | D9: =D10/D6 -> 0.32520325 | E9: =E10/E6 -> 0.15138748 | F9: =F10/F6 -> 0.01345297 | G9: =G10/G6 -> 0.023442623 | H9: =H10/H6 -> 0.16963064 | I9: =I10/I6 -> 0.25179459 | J9: =J10/J6 -> 0.32316645
B10: CASH+BANK+CI+MS | C10: =ATFL_BS_Consolidated!D47+ATFL_BS_Consolidated!D45 -> 89.73 | D10: =ATFL_BS_Consolidated!E47+ATFL_BS_Consolidated!E45 -> 160 | E10: =ATFL_BS_Consolidated!F47+ATFL_BS_Consolidated!F45 -> 89.47 | F10: =ATFL_BS_Consolidated!G47+ATFL_BS_Consolidated!G45 -> 10.87 | G10: =ATFL_BS_Consolidated!H47+ATFL_BS_Consolidated!H45 -> 34.32 | H10: =ATFL_BS_Consolidated!I47+ATFL_BS_Consolidated!I45 -> 372 | I10: =ATFL_BS_Consolidated!J47+ATFL_BS_Consolidated!J45 -> 456 | J10: =ATFL_BS_Consolidated!K47+ATFL_BS_Consolidated!K45 -> 497.03
B12: Profitability Ratios | C12: =C2 -> Mar'18 | D12: =D2 -> Mar'19 | E12: =E2 -> Mar'20 | F12: =F2 -> Mar'21 | G12: =G2 -> Mar'22 | H12: =H2 -> Mar'23 | I12: =I2 -> Mar'24 | J12: =J2 -> Mar'25
B13: GROSS PROFIT RATIO= GP/Total Renenue from Operation X100 | C13: =C14*100/C16 -> 29.320961 | D13: =D14*100/D16 -> 29.972077 | E13: =E14*100/E16 -> 36.566933 | F13: =F14*100/F16 -> 45.501769 | G13: =G14*100/G16 -> 28.436471 | H13: =H14*100/H16 -> 21.995889 | I13: =I14*100/I16 -> 27.806927 | J13: =J14*100/J16 -> 25.9364
B14: Grosss Profit (GP) = Total Renenue from Operation-COGS | C14: =C16-C15 -> 402.87 | D14: =D16-D15 -> 515.22 | E14: =E16-E15 -> 685.63 | F14: =F16-F15 -> 771.71 | G14: =G16-G15 -> 863.9 | H14: =H16-H15 -> 962.98 | I14: =I16-I15 -> 1244.36 | J14: =J16-J15 -> 1296.82
B15: COGS(Cost of Goods sold) = OP STK+PUR-CLOS STK+DE | C15: ='ATGL_P&L_Consolidated'!D27+'ATGL_P&L_Consolidated'!D29+'ATGL_P&L_Consolidated'!D33+'ATGL_P&L_Consolidated'!D35+'ATGL_P&L_Consolidated'!D39 -> 971.13 | D15: ='ATGL_P&L_Consolidated'!E27+'ATGL_P&L_Consolidated'!E29+'ATGL_P&L_Consolidated'!E33+'ATGL_P&L_Consolidated'!E35+'ATGL_P&L_Consolidated'!E39 -> 1203.78 | E15: ='ATGL_P&L_Consolidated'!F27+'ATGL_P&L_Consolidated'!F29+'ATGL_P&L_Consolidated'!F33+'ATGL_P&L_Consolidated'!F35+'ATGL_P&L_Consolidated'!F39 -> 1189.37 | F15: ='ATGL_P&L_Consolidated'!G27+'ATGL_P&L_Consolidated'!G29+'ATGL_P&L_Consolidated'!G33+'ATGL_P&L_Consolidated'!G35+'ATGL_P&L_Consolidated'!G39 -> 924.29 | G15: ='ATGL_P&L_Consolidated'!H27+'ATGL_P&L_Consolidated'!H29+'ATGL_P&L_Consolidated'!H33+'ATGL_P&L_Consolidated'!H35+'ATGL_P&L_Consolidated'!H39 -> 2174.1 | H15: ='ATGL_P&L_Consolidated'!I27+'ATGL_P&L_Consolidated'!I29+'ATGL_P&L_Consolidated'!I33+'ATGL_P&L_Consolidated'!I35+'ATGL_P&L_Consolidated'!I39 -> 3415.02 | I15: ='ATGL_P&L_Consolidated'!J27+'ATGL_P&L_Consolidated'!J29+'ATGL_P&L_Consolidated'!J33+'ATGL_P&L_Consolidated'!J35+'ATGL_P&L_Consolidated'!J39 -> 3230.64 | J15: ='ATGL_P&L_Consolidated'!K27+'ATGL_P&L_Consolidated'!K29+'ATGL_P&L_Consolidated'!K33+'ATGL_P&L_Consolidated'!K35+'ATGL_P&L_Consolidated'!K39 -> 3703.18
B16: Total Renenue from Operation | C16: ='ATGL_P&L_Consolidated'!D23 -> 1374 | D16: ='ATGL_P&L_Consolidated'!E23 -> 1719 | E16: ='ATGL_P&L_Consolidated'!F23 -> 1875 | F16: ='ATGL_P&L_Consolidated'!G23 -> 1696 | G16: ='ATGL_P&L_Consolidated'!H23 -> 3038 | H16: ='ATGL_P&L_Consolidated'!I23 -> 4378 | I16: ='ATGL_P&L_Consolidated'!J23 -> 4475 | J16: ='ATGL_P&L_Consolidated'!K23 -> 5000
B17: OPERATING PROFIT RATIO=EBIT/TOT OP REVX100 | C17: =C18/C16*100 -> 22.124454 | D17: =D18/D16*100 -> 22.553229 | E17: =E18/E16*100 -> 29.029333 | F17: =F18/F16*100 -> 37.823113 | G17: =G18/G16*100 -> 22.721198 | H17: =H18/H16*100 -> 17.291 | I17: =I18/I16*100 -> 21.139665 | J17: =J18/J16*100 -> 18.58
B18: OPERATING PROFIT(EBIT) TOTAL OP REVENUES -ALL EXP EXCEPT INTEREST AND TAX | C18: =C16-('ATGL_P&L_Consolidated'!D25+'ATGL_P&L_Consolidated'!D55) -> 303.99 | D18: =D16-('ATGL_P&L_Consolidated'!E25+'ATGL_P&L_Consolidated'!E55) -> 387.69 | E18: =E16-('ATGL_P&L_Consolidated'!F25+'ATGL_P&L_Consolidated'!F55) -> 544.3 | F18: =F16-('ATGL_P&L_Consolidated'!G25+'ATGL_P&L_Consolidated'!G55) -> 641.48 | G18: =G16-('ATGL_P&L_Consolidated'!H25+'ATGL_P&L_Consolidated'!H55) -> 690.27 | H18: =H16-('ATGL_P&L_Consolidated'!I25+'ATGL_P&L_Consolidated'!I55) -> 757 | I18: =I16-('ATGL_P&L_Consolidated'!J25+'ATGL_P&L_Consolidated'!J55) -> 946 | J18: =J16-('ATGL_P&L_Consolidated'!K25+'ATGL_P&L_Consolidated'!K55) -> 929
B19: NET PROFIT RATIO=PAT/NET REVENUEX100 | C19: =C20/C21*100 -> 11.790393 | D19: =D20/D21*100 -> 13.321699 | E19: =E20/E21*100 -> 23.253333 | F19: =F20/F21*100 -> 27.299528 | G19: =G20/G21*100 -> 16.754444 | H19: =H20/H21*100 -> 12.471448 | I19: =I20/I21*100 -> 14.927374 | J19: =J20/J21*100 -> 13.08
B20: PROFIT AFTER TAX(PAT) | C20: ='ATGL_P&L_Consolidated'!D71 -> 162 | D20: ='ATGL_P&L_Consolidated'!E71 -> 229 | E20: ='ATGL_P&L_Consolidated'!F71 -> 436 | F20: ='ATGL_P&L_Consolidated'!G71 -> 463 | G20: ='ATGL_P&L_Consolidated'!H71 -> 509 | H20: ='ATGL_P&L_Consolidated'!I71 -> 546 | I20: ='ATGL_P&L_Consolidated'!J71 -> 668 | J20: ='ATGL_P&L_Consolidated'!K71 -> 654
B21: NET REVENUE | C21: ='ATGL_P&L_Consolidated'!D23 -> 1374 | D21: ='ATGL_P&L_Consolidated'!E23 -> 1719 | E21: ='ATGL_P&L_Consolidated'!F23 -> 1875 | F21: ='ATGL_P&L_Consolidated'!G23 -> 1696 | G21: ='ATGL_P&L_Consolidated'!H23 -> 3038 | H21: ='ATGL_P&L_Consolidated'!I23 -> 4378 | I21: ='ATGL_P&L_Consolidated'!J23 -> 4475 | J21: ='ATGL_P&L_Consolidated'!K23 -> 5000
B22: EARNINGS PER SHARE =PAT/NO OF EQ SHARES | C22: =C23/C26 -> 0.63035019 | D22: =D23/D26 -> 2.0818182 | E22: =E23/E26 -> 3.9636364 | F22: =F23/F26 -> 4.2090909 | G22: =G23/G26 -> 4.6272727 | H22: =H23/H26 -> 4.9636364 | I22: =I23/I26 -> 6.0727273 | J22: =J23/J26 -> 5.9454545
B23: PROFIT AFTER TAX(PAT) | C23: =C20 -> 162 | D23: =D20 -> 229 | E23: =E20 -> 436 | F23: =F20 -> 463 | G23: =G20 -> 509 | H23: =H20 -> 546 | I23: =I20 -> 668 | J23: =J20 -> 654
B24: NO OF EQUITY SHARES | C24: =ATFL_BS_Consolidated!D57 -> 257 | D24: =ATFL_BS_Consolidated!E57 -> 110 | E24: =ATFL_BS_Consolidated!F57 -> 110 | F24: =ATFL_BS_Consolidated!G57 -> 110 | G24: =ATFL_BS_Consolidated!H57 -> 110 | H24: =ATFL_BS_Consolidated!I57 -> 110 | I24: =ATFL_BS_Consolidated!J57 -> 110 | J24: =ATFL_BS_Consolidated!K57 -> 110
B25: FACE VALUE IS 1 | C25: 1 | D25: 1 | E25: 1 | F25: 1 | G25: 1 | H25: 1 | I25: 1 | J25: 1
B26: NO OF EQUITY SHARES= EQ SH CPL/ FACE VALUE OF SHARE | C26: =C24/C25 -> 257 | D26: =D24/D25 -> 110 | E26: =E24/E25 -> 110 | F26: =F24/F25 -> 110 | G26: =G24/G25 -> 110 | H26: =H24/H25 -> 110 | I26: =I24/I25 -> 110 | J26: =J24/J25 -> 110
B27: RETURN ON EQUITY=PROFIT AFTER TAX(PAT)/EQ SH FUNDSX100 | C27: =C28/C29*100 -> 18.642117 | D27: =D28/D29*100 -> 20.780399 | E27: =E28/E29*100 -> 29.639701 | F27: =F28/F29*100 -> 23.940021 | G27: =G28/G29*100 -> 21.067881 | H27: =H28/H29*100 -> 18.565114 | I27: =I28/I29*100 -> 18.659218 | J27: =J28/J29*100 -> 15.545519
B28: PROFIT AFTER TAX(PAT) | C28: =C20 -> 162 | D28: =D20 -> 229 | E28: =E20 -> 436 | F28: =F20 -> 463 | G28: =G20 -> 509 | H28: =H20 -> 546 | I28: =I20 -> 668 | J28: =J20 -> 654
B29: Equity Share Holder Fund | C29: =ATFL_BS_Consolidated!D55 -> 869 | D29: =ATFL_BS_Consolidated!E55 -> 1102 | E29: =ATFL_BS_Consolidated!F55 -> 1471 | F29: =ATFL_BS_Consolidated!G55 -> 1934 | G29: =ATFL_BS_Consolidated!H55 -> 2416 | H29: =ATFL_BS_Consolidated!I55 -> 2941 | I29: =ATFL_BS_Consolidated!J55 -> 3580 | J29: =ATFL_BS_Consolidated!K55 -> 4207
B30: RETURN ON CAPITAL EMPLOYED=EBIT/ CPL EMPLOYEDX100 | C30: =C31/C32*100 -> 12.468827 | D30: =D31/D32*100 -> 24.91581 | E30: =E31/E32*100 -> 28.875332 | F30: =F31/F32*100 -> 26.772955 | G30: =G31/G32*100 -> 23.391054 | H30: =H31/H32*100 -> 21.929316 | I30: =I31/I32*100 -> 19.786656 | J30: =J31/J32*100 -> 15.164871
B31: EBIT | C31: =C18 -> 303.99 | D31: =D18 -> 387.69 | E31: =E18 -> 544.3 | F31: =F18 -> 641.48 | G31: =G18 -> 690.27 | H31: =H18 -> 757 | I31: =I18 -> 946 | J31: =J18 -> 929
B32: CPL EMPLOYED=DEBT+EQUITY | C32: =ATFL_BS_Consolidated!D55+ATFL_BS_Consolidated!D63 -> 2438 | D32: =ATFL_BS_Consolidated!E55+ATFL_BS_Consolidated!E63 -> 1556 | E32: =ATFL_BS_Consolidated!F55+ATFL_BS_Consolidated!F63 -> 1885 | F32: =ATFL_BS_Consolidated!G55+ATFL_BS_Consolidated!G63 -> 2396 | G32: =ATFL_BS_Consolidated!H55+ATFL_BS_Consolidated!H63 -> 2951 | H32: =ATFL_BS_Consolidated!I55+ATFL_BS_Consolidated!I63 -> 3452 | I32: =ATFL_BS_Consolidated!J55+ATFL_BS_Consolidated!J63 -> 4781 | J32: =ATFL_BS_Consolidated!K55+ATFL_BS_Consolidated!K63 -> 6126
B33: CPL EMP=TOTAL EQ SH FUNDS+ TOTAL NC LIABILITIES
B35: Solvency Ratios | C35: =C2 -> Mar'18 | D35: =D2 -> Mar'19 | E35: =E2 -> Mar'20 | F35: =F2 -> Mar'21 | G35: =G2 -> Mar'22 | H35: =H2 -> Mar'23 | I35: =I2 -> Mar'24 | J35: =J2 -> Mar'25
B36: DEBT EQUITY RATIO=LONG TERM DEBT/EQUITY | C36: =C37/C38 -> 1.8055236 | D36: =D37/D38 -> 0.41197822 | E36: =E37/E38 -> 0.2814412 | F36: =F37/F38 -> 0.23888314 | G36: =G37/G38 -> 0.2214404 | H36: =H37/H38 -> 0.17375043 | I36: =I37/I38 -> 0.33547486 | J36: =J37/J38 -> 0.45614452
B37: DEBT | C37: =ATFL_BS_Consolidated!D63 -> 1569 | D37: =ATFL_BS_Consolidated!E63 -> 454 | E37: =ATFL_BS_Consolidated!F63 -> 414 | F37: =ATFL_BS_Consolidated!G63 -> 462 | G37: =ATFL_BS_Consolidated!H63 -> 535 | H37: =ATFL_BS_Consolidated!I63 -> 511 | I37: =ATFL_BS_Consolidated!J63 -> 1201 | J37: =ATFL_BS_Consolidated!K63 -> 1919
B38: EQUITY = DEN FOR ROE | C38: =ATFL_BS_Consolidated!D55 -> 869 | D38: =ATFL_BS_Consolidated!E55 -> 1102 | E38: =ATFL_BS_Consolidated!F55 -> 1471 | F38: =ATFL_BS_Consolidated!G55 -> 1934 | G38: =ATFL_BS_Consolidated!H55 -> 2416 | H38: =ATFL_BS_Consolidated!I55 -> 2941 | I38: =ATFL_BS_Consolidated!J55 -> 3580 | J38: =ATFL_BS_Consolidated!K55 -> 4207
B39: DEBT CAPITAL RATIO=DEBT /(DEBT+EQUITY) | C39: =C37/(C37+C38) -> 0.6435603 | D39: =D37/(D37+D38) -> 0.29177378 | E39: =E37/(E37+E38) -> 0.21962865 | F39: =F37/(F37+F38) -> 0.19282137 | G39: =G37/(G37+G38) -> 0.18129448 | H39: =H37/(H37+H38) -> 0.14803013 | I39: =I37/(I37+I38) -> 0.25120268 | J39: =J37/(J37+J38) -> 0.31325498
B41: INTEREST COVERAGE RATIO= EBIT/INT PAID | C41: =C18/C42 -> 2.43192 | D41: =D18/D42 -> 4.3148581 | E41: =E18/E42 -> 13.25944 | F41: =F18/F42 -> 15.846838 | G41: =G18/G42 -> 13.09065 | H41: =H18/H42 -> 9.6519189 | I41: =I18/I42 -> 8.5225225 | J41: =J18/J42 -> 9.1980198
B42: INTEREST PAID | C42: ='ATGL_P&L_Consolidated'!D51 -> 125 | D42: ='ATGL_P&L_Consolidated'!E51 -> 89.85 | E42: ='ATGL_P&L_Consolidated'!F51 -> 41.05 | F42: ='ATGL_P&L_Consolidated'!G51 -> 40.48 | G42: ='ATGL_P&L_Consolidated'!H51 -> 52.73 | H42: ='ATGL_P&L_Consolidated'!I51 -> 78.43 | I42: ='ATGL_P&L_Consolidated'!J51 -> 111 | J42: ='ATGL_P&L_Consolidated'!K51 -> 101
B44: PROPRIETARY RATIO=EQ SH FUNDS/TOTAL CPL | C44: =ATFL_BS_Consolidated!D55/(C37+C38) -> 0.3564397 | D44: =ATFL_BS_Consolidated!E55/(D37+D38) -> 0.70822622 | E44: =ATFL_BS_Consolidated!F55/(E37+E38) -> 0.78037135 | F44: =ATFL_BS_Consolidated!G55/(F37+F38) -> 0.80717863 | G44: =ATFL_BS_Consolidated!H55/(G37+G38) -> 0.81870552 | H44: =ATFL_BS_Consolidated!I55/(H37+H38) -> 0.85196987 | I44: =ATFL_BS_Consolidated!J55/(I37+I38) -> 0.74879732 | J44: =ATFL_BS_Consolidated!K55/(J37+J38) -> 0.68674502
...

Sheet Analysis
B2: Liquidity Ratio | C2: Mar'18 | D2: Mar'19 | E2: Mar'20 | F2: Mar'21 | G2: Mar'22 | H2: Mar'23 | I2: Mar'24 | J2: Mar'25
B3: ='ATGL_Finanacial Ratios'!B4 -> CURRENT RATIO = Current Assets/Current Liability | C3: ='ATGL_Finanacial Ratios'!C4 -> 1.7884615 | D3: ='ATGL_Finanacial Ratios'!D4 -> 1.3699187 | E3: ='ATGL_Finanacial Ratios'!E4 -> 0.94416244 | F3: ='ATGL_Finanacial Ratios'!F4 -> 0.2759901 | G3: ='ATGL_Finanacial Ratios'!G4 -> 0.24726776 | H3: ='ATGL_Finanacial Ratios'!H4 -> 0.39124487 | I3: ='ATGL_Finanacial Ratios'!I4 -> 0.56985091 | J3: ='ATGL_Finanacial Ratios'!J4 -> 0.72886866
B4: ='ATGL_Finanacial Ratios'!B7 -> QUICK RATIO = QuiCK Asset/Current Liability | C4: ='ATGL_Finanacial Ratios'!C7 -> 1.6726374 | D4: ='ATGL_Finanacial Ratios'!D7 -> 1.2805691 | E4: ='ATGL_Finanacial Ratios'!E7 -> 0.87428088 | F4: ='ATGL_Finanacial Ratios'!F7 -> 0.21162129 | G4: ='ATGL_Finanacial Ratios'!G7 -> 0.1948224 | H4: ='ATGL_Finanacial Ratios'!H7 -> 0.34976744 | I4: ='ATGL_Finanacial Ratios'!I7 -> 0.51509111 | J4: ='ATGL_Finanacial Ratios'!J7 -> 0.65344603
B5: ='ATGL_Finanacial Ratios'!B9 -> ABSOLUTE LIQUID RATIO= CASH+BANK+CI+MS/Current Liability | C5: ='ATGL_Finanacial Ratios'!C9 -> 0.24651099 | D5: ='ATGL_Finanacial Ratios'!D9 -> 0.32520325 | E5: ='ATGL_Finanacial Ratios'!E9 -> 0.15138748 | F5: ='ATGL_Finanacial Ratios'!F9 -> 0.01345297 | G5: ='ATGL_Finanacial Ratios'!G9 -> 0.023442623 | H5: ='ATGL_Finanacial Ratios'!H9 -> 0.16963064 | I5: ='ATGL_Finanacial Ratios'!I9 -> 0.25179459 | J5: ='ATGL_Finanacial Ratios'!J9 -> 0.32316645
B8: Profitability Ratios | C8: Mar'18 | D8: Mar'19 | E8: Mar'20 | F8: Mar'21 | G8: Mar'22 | H8: Mar'23 | I8: Mar'24 | J8: Mar'25
B9: ='ATGL_Finanacial Ratios'!B13 -> GROSS PROFIT RATIO= GP/Total Renenue from Operation X100 | C9: ='ATGL_Finanacial Ratios'!C13 -> 29.320961 | D9: ='ATGL_Finanacial Ratios'!D13 -> 29.972077 | E9: ='ATGL_Finanacial Ratios'!E13 -> 36.566933 | F9: ='ATGL_Finanacial Ratios'!F13 -> 45.501769 | G9: ='ATGL_Finanacial Ratios'!G13 -> 28.436471 | H9: ='ATGL_Finanacial Ratios'!H13 -> 21.995889 | I9: ='ATGL_Finanacial Ratios'!I13 -> 27.806927 | J9: ='ATGL_Finanacial Ratios'!J13 -> 25.9364
B10: ='ATGL_Finanacial Ratios'!B17 -> OPERATING PROFIT RATIO=EBIT/TOT OP REVX100 | C10: ='ATGL_Finanacial Ratios'!C17 -> 22.124454 | D10: ='ATGL_Finanacial Ratios'!D17 -> 22.553229 | E10: ='ATGL_Finanacial Ratios'!E17 -> 29.029333 | F10: ='ATGL_Finanacial Ratios'!F17 -> 37.823113 | G10: ='ATGL_Finanacial Ratios'!G17 -> 22.721198 | H10: ='ATGL_Finanacial Ratios'!H17 -> 17.291 | I10: ='ATGL_Finanacial Ratios'!I17 -> 21.139665 | J10: ='ATGL_Finanacial Ratios'!J17 -> 18.58
B11: ='ATGL_Finanacial Ratios'!B19 -> NET PROFIT RATIO=PAT/NET REVENUEX100 | C11: ='ATGL_Finanacial Ratios'!C19 -> 11.790393 | D11: ='ATGL_Finanacial Ratios'!D19 -> 13.321699 | E11: ='ATGL_Finanacial Ratios'!E19 -> 23.253333 | F11: ='ATGL_Finanacial Ratios'!F19 -> 27.299528 | G11: ='ATGL_Finanacial Ratios'!G19 -> 16.754444 | H11: ='ATGL_Finanacial Ratios'!H19 -> 12.471448 | I11: ='ATGL_Finanacial Ratios'!I19 -> 14.927374 | J11: ='ATGL_Finanacial Ratios'!J19 -> 13.08
B12: ='ATGL_Finanacial Ratios'!B22 -> EARNINGS PER SHARE =PAT/NO OF EQ SHARES | C12: ='ATGL_Finanacial Ratios'!C22 -> 0.63035019 | D12: ='ATGL_Finanacial Ratios'!D22 -> 2.0818182 | E12: ='ATGL_Finanacial Ratios'!E22 -> 3.9636364 | F12: ='ATGL_Finanacial Ratios'!F22 -> 4.2090909 | G12: ='ATGL_Finanacial Ratios'!G22 -> 4.6272727 | H12: ='ATGL_Finanacial Ratios'!H22 -> 4.9636364 | I12: ='ATGL_Finanacial Ratios'!I22 -> 6.0727273 | J12: ='ATGL_Finanacial Ratios'!J22 -> 5.9454545
B13: ='ATGL_Finanacial Ratios'!B27 -> RETURN ON EQUITY=PROFIT AFTER TAX(PAT)/EQ SH FUNDSX100 | C13: ='ATGL_Finanacial Ratios'!C27 -> 18.642117 | D13: ='ATGL_Finanacial Ratios'!D27 -> 20.780399 | E13: ='ATGL_Finanacial Ratios'!E27 -> 29.639701 | F13: ='ATGL_Finanacial Ratios'!F27 -> 23.940021 | G13: ='ATGL_Finanacial Ratios'!G27 -> 21.067881 | H13: ='ATGL_Finanacial Ratios'!H27 -> 18.565114 | I13: ='ATGL_Finanacial Ratios'!I27 -> 18.659218 | J13: ='ATGL_Finanacial Ratios'!J27 -> 15.545519
B14: ='ATGL_Finanacial Ratios'!B30 -> RETURN ON CAPITAL EMPLOYED=EBIT/ CPL EMPLOYEDX100 | C14: ='ATGL_Finanacial Ratios'!C30 -> 12.468827 | D14: ='ATGL_Finanacial Ratios'!D30 -> 24.91581 | E14: ='ATGL_Finanacial Ratios'!E30 -> 28.875332 | F14: ='ATGL_Finanacial Ratios'!F30 -> 26.772955 | G14: ='ATGL_Finanacial Ratios'!G30 -> 23.391054 | H14: ='ATGL_Finanacial Ratios'!H30 -> 21.929316 | I14: ='ATGL_Finanacial Ratios'!I30 -> 19.786656 | J14: ='ATGL_Finanacial Ratios'!J30 -> 15.164871
B17: Solvency Ratios | C17: Mar'18 | D17: Mar'19 | E17: Mar'20 | F17: Mar'21 | G17: Mar'22 | H17: Mar'23 | I17: Mar'24 | J17: Mar'25
B18: ='ATGL_Finanacial Ratios'!B36 -> DEBT EQUITY RATIO=LONG TERM DEBT/EQUITY | C18: ='ATGL_Finanacial Ratios'!C36 -> 1.8055236 | D18: ='ATGL_Finanacial Ratios'!D36 -> 0.41197822 | E18: ='ATGL_Finanacial Ratios'!E36 -> 0.2814412 | F18: ='ATGL_Finanacial Ratios'!F36 -> 0.23888314 | G18: ='ATGL_Finanacial Ratios'!G36 -> 0.2214404 | H18: ='ATGL_Finanacial Ratios'!H36 -> 0.17375043 | I18: ='ATGL_Finanacial Ratios'!I36 -> 0.33547486 | J18: ='ATGL_Finanacial Ratios'!J36 -> 0.45614452
B19: ='ATGL_Finanacial Ratios'!B39 -> DEBT CAPITAL RATIO=DEBT /(DEBT+EQUITY) | C19: ='ATGL_Finanacial Ratios'!C39 -> 0.6435603 | D19: ='ATGL_Finanacial Ratios'!D39 -> 0.29177378 | E19: ='ATGL_Finanacial Ratios'!E39 -> 0.21962865 | F19: ='ATGL_Finanacial Ratios'!F39 -> 0.19282137 | G19: ='ATGL_Finanacial Ratios'!G39 -> 0.18129448 | H19: ='ATGL_Finanacial Ratios'!H39 -> 0.14803013 | I19: ='ATGL_Finanacial Ratios'!I39 -> 0.25120268 | J19: ='ATGL_Finanacial Ratios'!J39 -> 0.31325498
B20: ='ATGL_Finanacial Ratios'!B41 -> INTEREST COVERAGE RATIO= EBIT/INT PAID | C20: ='ATGL_Finanacial Ratios'!C41 -> 2.43192 | D20: ='ATGL_Finanacial Ratios'!D41 -> 4.3148581 | E20: ='ATGL_Finanacial Ratios'!E41 -> 13.25944 | F20: ='ATGL_Finanacial Ratios'!F41 -> 15.846838 | G20: ='ATGL_Finanacial Ratios'!G41 -> 13.09065 | H20: ='ATGL_Finanacial Ratios'!H41 -> 9.6519189 | I20: ='ATGL_Finanacial Ratios'!I41 -> 8.5225225 | J20: ='ATGL_Finanacial Ratios'!J41 -> 9.1980198
B21: ='ATGL_Finanacial Ratios'!B44 -> PROPRIETARY RATIO=EQ SH FUNDS/TOTAL CPL | C21: ='ATGL_Finanacial Ratios'!C44 -> 0.3564397 | D21: ='ATGL_Finanacial Ratios'!D44 -> 0.70822622 | E21: ='ATGL_Finanacial Ratios'!E44 -> 0.78037135 | F21: ='ATGL_Finanacial Ratios'!F44 -> 0.80717863 | G21: ='ATGL_Finanacial Ratios'!G44 -> 0.81870552 | H21: ='ATGL_Finanacial Ratios'!H44 -> 0.85196987 | I21: ='ATGL_Finanacial Ratios'!I44 -> 0.74879732 | J21: ='ATGL_Finanacial Ratios'!J44 -> 0.68674502
B24: Turnover Ratio/Efficiency Ratios | C24: Mar'18 | D24: Mar'19 | E24: Mar'20 | F24: Mar'21 | G24: Mar'22 | H24: Mar'23 | I24: Mar'24 | J24: Mar'25
B25: ='ATGL_Finanacial Ratios'!B47 -> Debtors Turnover Ratio = Net Credit Sales/Average Debtors | C25: ='ATGL_Finanacial Ratios'!C47 -> 12.279369 | D25: ='ATGL_Finanacial Ratios'!D47 -> 23.881634 | E25: ='ATGL_Finanacial Ratios'!E47 -> 22.703881 | F25: ='ATGL_Finanacial Ratios'!F47 -> 11.656357 | G25: ='ATGL_Finanacial Ratios'!G47 -> 12.079523 | H25: ='ATGL_Finanacial Ratios'!H47 -> 12.060606 | I25: ='ATGL_Finanacial Ratios'!I47 -> 10.731415 | J25: ='ATGL_Finanacial Ratios'!J47 -> 11.123471
B26: ='ATGL_Finanacial Ratios'!B51 -> Creditors Turnover Ratio = NetCredit Purchases/Average Payables | C26: ='ATGL_Finanacial Ratios'!C51 -> 7.2418257 | D26: ='ATGL_Finanacial Ratios'!D51 -> 11.708269 | E26: ='ATGL_Finanacial Ratios'!E51 -> 10.677609 | F26: ='ATGL_Finanacial Ratios'!F51 -> 5.4604255 | G26: ='ATGL_Finanacial Ratios'!G51 -> 8.1612262 | H26: ='ATGL_Finanacial Ratios'!H51 -> 9.689325 | I26: ='ATGL_Finanacial Ratios'!I51 -> 8.8430435 | J26: ='ATGL_Finanacial Ratios'!J51 -> 11.09661
B27: ='ATGL_Finanacial Ratios'!B56 -> Float | C27: ='ATGL_Finanacial Ratios'!C56 -> -20.677 | D27: ='ATGL_Finanacial Ratios'!D56 -> -15.890838 | E27: ='ATGL_Finanacial Ratios'!E56 -> -18.107135 | F27: ='ATGL_Finanacial Ratios'!F56 -> -35.531223 | G27: ='ATGL_Finanacial Ratios'!G56 -> -14.507246 | H27: ='ATGL_Finanacial Ratios'!H56 -> -7.4065038 | I27: ='ATGL_Finanacial Ratios'!I56 -> -7.2630918 | J27: ='ATGL_Finanacial Ratios'!J56 -> -0.079428059
B28: ='ATGL_Finanacial Ratios'!B58 -> Inventory Turnover Ratio = COGS/Average Inventory at Cost | C28: ='ATGL_Finanacial Ratios'!C58 -> 22.552949 | D28: ='ATGL_Finanacial Ratios'!D58 -> 28.237861 | E28: ='ATGL_Finanacial Ratios'!E58 -> 25.492873 | F28: ='ATGL_Finanacial Ratios'!F58 -> 14.353444 | G28: ='ATGL_Finanacial Ratios'!G58 -> 25.922261 | H28: ='ATGL_Finanacial Ratios'!H58 -> 35.923 | I28: ='ATGL_Finanacial Ratios'!I58 -> 30.028721 | J28: ='ATGL_Finanacial Ratios'!J58 -> 33.361982
B29: ='ATGL_Finanacial Ratios'!B61 -> Working Capital Turnover Ratio = COGS/Net WorkingCapital | C29: ='ATGL_Finanacial Ratios'!C61 -> 3.3837282 | D29: ='ATGL_Finanacial Ratios'!D61 -> 6.6141758 | E29: ='ATGL_Finanacial Ratios'!E61 -> -36.041515 | F29: ='ATGL_Finanacial Ratios'!F61 -> -1.5799829 | G29: ='ATGL_Finanacial Ratios'!G61 -> -1.9728675 | H29: ='ATGL_Finanacial Ratios'!H61 -> -2.5580674 | I29: ='ATGL_Finanacial Ratios'!I61 -> -4.147163 | J29: ='ATGL_Finanacial Ratios'!J61 -> -8.8805276
B30: ='ATGL_Finanacial Ratios'!B64 -> Fixed Asset Turnover Ratio = Revenue from operations/Net Fixed Assets | C30: ='ATGL_Finanacial Ratios'!C64 -> 1.3753754 | D30: ='ATGL_Finanacial Ratios'!D64 -> 1.4692308 | E30: ='ATGL_Finanacial Ratios'!E64 -> 1.2175325 | F30: ='ATGL_Finanacial Ratios'!F64 -> 0.8173494 | G30: ='ATGL_Finanacial Ratios'!G64 -> 1.0461433 | H30: ='ATGL_Finanacial Ratios'!H64 -> 1.1072332 | I30: ='ATGL_Finanacial Ratios'!I64 -> 0.95701454 | J30: ='ATGL_Finanacial Ratios'!J64 -> 0.90530509
B33: VALUATION RATIOS | C33: Mar'18 | D33: Mar'19 | E33: Mar'20 | F33: Mar'21 | G33: Mar'22 | H33: Mar'23 | I33: Mar'24 | J33: Mar'25
B34: ='ATGL_Finanacial Ratios'!B68 -> PRICE EARNINGS RATIO=MPS/EPS | C34: ='ATGL_Finanacial Ratios'!C68 -> 159.91111 | D34: ='ATGL_Finanacial Ratios'!D68 -> 78.152838 | E34: ='ATGL_Finanacial Ratios'!E68 -> 94.761468 | F34: ='ATGL_Finanacial Ratios'!F68 -> 409.06695 | G34: ='ATGL_Finanacial Ratios'!G68 -> 798.06189 | H34: ='ATGL_Finanacial Ratios'!H68 -> 199.03755 | I34: ='ATGL_Finanacial Ratios'!I68 -> 125.3226 | J34: ='ATGL_Finanacial Ratios'!J68 -> 95.316514
B35: ='ATGL_Finanacial Ratios'!B71 -> PRICE BOOK RATIO=MPS/BVPS | C35: ='ATGL_Finanacial Ratios'!C71 -> 29.810817 | D35: ='ATGL_Finanacial Ratios'!D71 -> 16.240472 | E35: ='ATGL_Finanacial Ratios'!E71 -> 28.087016 | F35: ='ATGL_Finanacial Ratios'!F71 -> 97.930714 | G35: ='ATGL_Finanacial Ratios'!G71 -> 168.13473 | H35: ='ATGL_Finanacial Ratios'!H71 -> 36.951547 | I35: ='ATGL_Finanacial Ratios'!I71 -> 23.384218 | J35: ='ATGL_Finanacial Ratios'!J71 -> 14.817447
B40: CA Vs CL | C40: Mar'18 | D40: Mar'19 | E40: Mar'20 | F40: Mar'21 | G40: Mar'22 | H40: Mar'23 | I40: Mar'24 | J40: Mar'25
B41: Current Assets | C41: 651 | D41: 674 | E41: 558 | F41: 223 | G41: 362 | H41: 858 | I41: 1032 | J41: 1121 | L41: 1253
B42: Current Liabilities | C42: 364 | D42: 492 | E42: 591 | F42: 808 | G42: 1464 | H42: 2193 | I42: 1811 | J42: 1538

Sheet ATFL_BS_Consolidated
B2: Source of data download | D2: https://www.tijorifinance.com/company/adani-gas-ltd/financials/#balance_sheet
B3: Date of downöpad | D3: 46027
B4: Balance Sheet
B5: Consolidated
B6: Standalone
B7: View Summary
B8: Adani Total Gas Ltd.
B9: Gujarat Gas
B10: Indraprastha Gas
B12: Add Company
B13: ?
B14: A-
B15: A+
D16: Mar'18 | E16: Mar'19 | F16: Mar'20 | G16: Mar'21 | H16: Mar'22 | I16: Mar'23 | J16: Mar'24 | K16: Mar'25 | L16: Sep'25
B17: In Rs. Cr. | D17: 2803 | E17: 2048 | F17: 2476 | G17: 3204 | H17: 4415 | I17: 5645 | J17: 6592 | K17: 7665 | L17: 8743
B18: Assets
D19: 2052 | E19: 1273 | F19: 1828 | G19: 2870 | H19: 3917 | I19: 4612 | J19: 5335 | K19: 6270 | L19: 7490
B20: Non Current Assets
D21: 1065 | E21: 1214 | F21: 1483 | G21: 1728 | H21: 2163 | I21: 2878 | J21: 3875 | K21: 4553 | L21: —
B22: Gross Block
D23: 168 | E23: 234 | F23: 285 | G23: 348 | H23: 430 | I23: 544 | J23: 701 | K23: 902 | L23: —
B24: Less: Accumulated Depreciation
D25: — | E25: — | F25: — | G25: — | H25: — | I25: — | J25: — | K25: — | L25: —
B26: Less: Impairment of Assets
D27: 897 | E27: 980 | F27: 1198 | G27: 1379 | H27: 1733 | I27: 2335 | J27: 3174 | K27: 3651 | L27: 3823
B28: Net Block
D29: — | E29: — | F29: — | G29: — | H29: — | I29: — | J29: — | K29: — | L29: —
B30: Lease Adjustment A/c
D31: 102 | E31: 190 | F31: 342 | G31: 696 | H31: 1171 | I31: 1619 | J31: 1502 | K31: 1872 | L31: 1834
B32: Capital Work in Progress
D33: 114 | E33: 176 | F33: 282 | G33: 417 | H33: 634 | I33: 682 | J33: 706 | K33: 783 | L33: 595
B34: Long Term Investments
D35: 1037 | E35: 25.96 | F35: 96.62 | G35: 447 | H35: 476 | I35: 151 | J35: 177 | K35: 238 | L35: —
B36: Long Term Loans & Advances
D37: 1.82 | E37: 1.97 | F37: 0 | G37: 40 | H37: 40 | I37: — | J37: 0 | K37: — | L37: 363
B38: Other Non Current Assets
D39: 651 | E39: 674 | F39: 558 | G39: 223 | H39: 362 | I39: 858 | J39: 1032 | K39: 1121 | L39: 1253
B40: Current Assets
D41: 42.16 | E41: 43.96 | F41: 41.3 | G41: 52.01 | H41: 76.78 | I41: 90.96 | J41: 99.17 | K41: 116 | L41: 106
B42: Inventory
...

Sheet ATGL_P&L_Consolidated
B3: Source of data download | D3: https://www.tijorifinance.com/company/adani-gas-ltd/financials/#profit_and_loss
B4: Date of downöpad | D4: 46027
B5: Profit & Loss
B6: Consolidated
B7: Standalone
B8: View Summary
B9: Adani Total Gas Ltd.
B10: Gujarat Gas
B11: Indraprastha Gas
B13: Add Company
B14: ?
B15: A-
B16: A+
B18: In Rs. Cr. | D18: Mar'18 | E18: Mar'19 | F18: Mar'20 | G18: Mar'21 | H18: Mar'22 | I18: Mar'23 | J18: Mar'24 | K18: Mar'25 | L18: Sep'25
B19: Gross Sales | D19: 1374 | E19: 1719 | F19: 1875 | G19: 1696 | H19: 3038 | I19: 4378 | J19: 4475 | K19: 5000 | L19: 0
B21: Less: Excise Duty | D21: 83.99 | E21: 105 | F21: 116 | G21: 88.87 | H21: 169 | I21: 305 | J21: 342 | K21: 412 | L21: 0
B23: Net Sales | D23: 1374 | E23: 1719 | F23: 1875 | G23: 1696 | H23: 3038 | I23: 4378 | J23: 4475 | K23: 5000 | L23: 5929
B25: Operating Expenses | D25: 1009 | E25: 1264 | F25: 1280 | G25: 992 | H25: 2265 | I25: 3508 | J25: 3371 | K25: 3867 | L25: 4809
B27: Increase/Decrease in Stock | D27: 0.64 | E27: 5.44 | F27: 0.34 | G27: -1.08 | H27: -8.87 | I27: 3.05 | J27: -0.54 | K27: -2.5 | L27: -2.14
B29: Raw Material | D29: 872 | E29: 1087 | F29: 1060 | G29: 771 | H29: 1939 | I29: 3083 | J29: 2848 | K29: 3276 | L29: 3720
B31: Material Cost (%) | D31: 63.56 | E31: 63.56 | F31: 56.55 | G31: 45.39 | H31: 63.52 | I31: 70.49 | J31: 63.64 | K31: 65.47 | L31: 62.71
B33: Other Manufacturing Expenses | D33: 32.79 | E33: 37.05 | F33: 46.18 | G33: 75.75 | H33: 135 | I33: 190 | J33: 225 | K33: 258 | L33: 0
B35: Employee Cost | D35: 38.9 | E35: 42 | F35: 47.46 | G35: 51.52 | H35: 54.73 | I35: 55.68 | J35: 66.71 | K35: 56.68 | L35: 53.69
B37: Selling and Distribution Expenses | D37: 2.87 | E37: 9.28 | F37: 5.04 | G37: 3.3 | H37: 9.1 | I37: 9.94 | J37: 0 | K37: 0 | L37: 0
B39: Power & Fuel Cost | D39: 26.8 | E39: 32.29 | F39: 35.39 | G39: 27.1 | H39: 54.24 | I39: 83.29 | J39: 91.47 | K39: 115 | L39: 0
B41: General and Administration Expenses | D41: 27.7 | E41: 44.79 | F41: 80.06 | G41: 55.76 | H41: 70.14 | I41: 55.56 | J41: 95.9 | K41: 103 | L41: 0
... B83: Dividend Payout Ratio(%) | D83: 0 | E83: 12.02 | F83: 6.3 | G83: 5.94 | H83: 5.4 | I83: 5.03 | J83: 4.12 | K83: 4.2 | L83: 0
B85: TTM Values as of Sep 2025

Sheet Peers&Competitor
B6: Metric | C6: ATGL | D6: GAIL | E6: Gujarat Gas | F6: IGL
B7: Market Cap (₹ Cr) | C7: 61210 | D7: 108068 | E7: 27156 | F7: 25851
B8: Revenue (₹ Cr, FY25) | C8: ~5,000 | D8: 141903 | E8: 16487 | F8: 14928
B9: PAT (₹ Cr, FY25) | C9: ~640 | D9: ~10,960 | E9: ~281 | F9: ~372
B10: PE Ratio (TTM) | C10: ~94–100 | D10: ~8.7 | E10: ~24.3 | F10: ~19.0
B11: ROE (%) | C11: ~16.4% | D11: 0.135 | E11: 0.295 | F11: 0.195
B12: Dividend Yield (%) | C12: ~0.04% | D12: 0.046 | E12: 0.015 | F12: 0.038
